Workbook

Sheet Guide
B1: MERIDIAN BUSINESS BANK — BOTTOM-UP UNIT ECONOMICS MODEL
B3: What this is
B4: • A bottom-up model of Meridian's Business Banking unit (45,000 customers) built with the method of the public uk-sme-bank-reference-model: bound the operating unit, derive every cost from activity drivers (transaction intensity I, customer load L), build whole costs including risk and capital, and check per-product economic profit after a cost-of-equity charge.
B5: • All numbers from the Meridian internal fact pack. Three inputs the fact pack declares missing — commercial card interchange, workout hours, RM time-split — plus two gaps found while building (BCA credit interest, FX margin) are FLAGGED in red/pink and carried as [low, high] bands, with their P&L swing shown on the P&L tab.
B7: Tabs
B8: • Inputs — every assumption with source; red/pink = missing-input assumption with band.
B9: • 1. Customers — Step 1 bounding: 45,000 customers → product volumes and balances.
B10: • 2. Revenues — margins vs FTP (floating = Bank Rate; term = +55bps; stable deposits get the liquidity-adjusted FTP: float − 14%×0.9% + 45bps behavioural credit).
B11: • 3. HR & Activity — every FTE from activity drivers; the RM originate/steward/defend system with the flagged 50/30/20 split.
B12: • 4. Running Costs — direct + HQ pools + change-the-bank; ABC attribution memo to the causality limit.
B13: • 5. Risk & Capital — EL (PD × LGD), credit + op-risk RWAs, 13.5% CET1 equity, 11.5% required return.
B14: • 6. Unit Economics — per-product whole-cost economics; bridge check vs the P&L must tie to ~0.
... B22: • Working products derived from CTM state changes, never brainstormed. Every activity has a named volume driver — no '% of revenue'. Every money outflow appears as a flow (fidelity table, tab 8). Costs attributed only as far as causality runs; joint costs held as a portfolio hurdle. Capital charged at cost of equity → economic profit per product. Benefits without evidence (stewardship PD reduction, defence churn credit) set to zero rather than assumed.

Sheet Inputs
B1: INPUTS & ASSUMPTIONS — MERIDIAN BUSINESS BANK BOTTOM-UP MODEL
B2: Blue = fact-pack input. RED on pink = input MISSING from the fact pack — flagged, carried as a [low, high] band, never silently invented.
B4: A. MARKET, FUNDING & FUNDS-TRANSFER PRICES
B5: Item | C5: Value | D5: Unit | E5: Low | F5: High | G5: Source / note
B6: Bank of England Bank Rate | C6: 0.0375 | D6: % p.a. | G6: Meridian fact pack
B7: Term funding premium over Bank Rate | C7: 0.0055 | D7: % p.a. | G7: Meridian fact pack: +55bps
B8: FTP — floating (= Bank Rate) | C8: ='Inputs'!$C$6 | D8: % p.a. | G8: Internal transfer price; method per reference model
B9: FTP — term (= Bank Rate + premium) | C9: ='Inputs'!$C$6+'Inputs'!$C$7 | D9: % p.a. | G9: Charged to term lending; credited to term deposits
B10: Liquidity buffer held against deposits | C10: 0.14 | D10: % of deposits | G10: Meridian fact pack
B11: Yield give-up on the liquidity buffer vs Bank Rate | C11: 0.009 | D11: % p.a. | G11: Meridian fact pack
B12: Behavioural term credit for stable non-maturing deposits | C12: 0.0045 | D12: % p.a. | G12: Meridian fact pack: 45bps
B13: FTP credited to stable deposits (float − liq charge + behavioural credit) | C13: ='Inputs'!$C$8-'Inputs'!$C$10*'Inputs'!$C$11+'Inputs'!$C$12 | D13: % p.a. | G13: Applied to current accounts and instant savings — liquidity-adjusted deposit FTP per reference model
B14: FTP credited to term deposits (term − liq charge) | C14: ='Inputs'!$C$9-'Inputs'!$C$10*'Inputs'!$C$11 | D14: % p.a. | G14: Applied to 1-yr fixed deposits (already termed; no behavioural uplift)
B15: B. OPERATING UNIT — MERIDIAN BUSINESS BANKING (Step 1: bounding)
B16: Item | C16: Value | D16: Unit | E16: Low | F16: High | G16: Source / note
B17: Reachable business market (R) | C17: 300000 | D17: businesses | G17: Meridian fact pack
B18: Penetration (P) — implied by 45,000 customers | C18: 0.15 | D18: % of reachable | G18: Meridian fact pack: 45,000 / 300,000 = 15%
B19: Annual customer churn (replaced at steady state) | C19: 0.1 | D19: % p.a. | G19: Meridian fact pack
B20: Share of customers that are relationship-managed | C20: 0.12 | D20: % | G20: Meridian fact pack: segment boundary — larger/complex customers get a named RM; the rest served digitally
B21: Customers per relationship manager (L) | C21: 90 | D21: customers | G21: Meridian fact pack
B22: C. PRODUCT HOLDINGS & BALANCES (per customer)
B23: Item | C23: Value | D23: Unit | E23: Low | F23: High | G23: Source / note
B24: Business current account — penetration | C24: 1 | D24: % | G24: Meridian fact pack: anchor product
B25: BCA — average credit balance | C25: 14000 | D25: £/account | G25: Meridian fact pack
B26: Instant-access savings — penetration | C26: 0.35 | D26: % | G26: Meridian fact pack
B27: Instant-access savings — average balance | C27: 22000 | D27: £/account | G27: Meridian fact pack
B28: Fixed deposits (1yr) — penetration | C28: 0.1 | D28: % | G28: Meridian fact pack
B29: Fixed deposits — average balance | C29: 60000 | D29: £/account | G29: Meridian fact pack
B30: Term loans — penetration | C30: 0.09 | D30: % | G30: Meridian fact pack
B31: Term loans — average balance | C31: 180000 | D31: £/loan | G31: Meridian fact pack
B32: Term loans — average life | C32: 5 | D32: years | G32: Meridian fact pack: drives origination volume & fee amortisation
B33: Overdrafts — penetration | C33: 0.2 | D33: % | G33: Meridian fact pack
B34: Overdrafts — average limit | C34: 12000 | D34: £/facility | G34: Meridian fact pack
B35: Overdrafts — average utilisation | C35: 0.4 | D35: % of limit | G35: Meridian fact pack
... B42: International payments — number per user per year | C42: 20 | D42: payments | G42: Meridian fact pack
B43: D. PRICING & FEES
B44: Item | C44: Value | D44: Unit | E44: Low | F44: High | G44: Source / note
B45: BCA — credit interest paid | C45: 0 | D45: % p.a. | E45: 0 | F45: 0.005 | G45: GAP FOUND: fact pack states fee & txn income but no BCA credit rate. Assumed 0% (typical); band 0–0.5%
B46: BCA — monthly account fee | C46: 6 | D46: £/month | G46: Meridian fact pack
B47: BCA — net transaction income | C47: 90 | D47: £/account/yr | G47: Meridian fact pack
...

Sheet 1. Customers
B1: STEP 1 — BOUNDING THE OPERATING UNIT
B2: The unit is Meridian's Business Banking segment: 45,000 customers, bounded by customer segment (12% relationship-managed at 90/RM; the mass served digitally). Modelled whole — no geographic slice needed.
B4: Customers at steady state (R × P) | C4: ='Inputs'!$C$17*'Inputs'!$C$18 | E4: 300,000 × 15% = 45,000 (fact pack)
B5: …of which relationship-managed | C5: ='1. Customers'!$C$4*'Inputs'!$C$20
B6: New customers onboarded per year (churn replacement) | C6: ='1. Customers'!$C$4*'Inputs'!$C$19 | E6: Defence effect held at 0 (no evidence) — gross churn drives onboarding & KYC
B8: PRODUCT VOLUMES & BALANCES
B9: Product | C9: Units | D9: Avg balance per unit (£) | E9: Total balances (£) | F9: Note
B10: Business current accounts | C10: ='1. Customers'!$C$4*'Inputs'!$C$24 | D10: ='Inputs'!$C$25 | E10: =C10*D10 | F10: Credit balances held
B11: Instant-access savings | C11: ='1. Customers'!$C$4*'Inputs'!$C$26 | D11: ='Inputs'!$C$27 | E11: =C11*D11
B12: Fixed deposits (1yr) | C12: ='1. Customers'!$C$4*'Inputs'!$C$28 | D12: ='Inputs'!$C$29 | E12: =C12*D12
B13: Business overdrafts | C13: ='1. Customers'!$C$4*'Inputs'!$C$33 | D13: ='Inputs'!$C$34*'Inputs'!$C$35 | E13: =C13*D13 | F13: Balance = limit × utilisation (drawn)
B14: Term loans | C14: ='1. Customers'!$C$4*'Inputs'!$C$30 | D14: ='Inputs'!$C$31 | E14: =C14*D14
B15: Business credit cards | C15: ='1. Customers'!$C$4*'Inputs'!$C$36 | D15: ='Inputs'!$C$39*'Inputs'!$C$38 | E15: =C15*D15 | F15: Avg interest-bearing balance per card
B16: Payments & FX (service users) | C16: ='1. Customers'!$C$4*'Inputs'!$C$40 | D16: =0 | E16: =C16*D16 | F16: No balance product
B17: Total customer deposits | E17: ='1. Customers'!$E$10+'1. Customers'!$E$11+'1. Customers'!$E$12
B18: Total lending balances (drawn) | E18: ='1. Customers'!$E$13+'1. Customers'!$E$14+'1. Customers'!$E$15
D19: ='1. Customers'!$E$18/'1. Customers'!$E$17 | E19: Loan-to-deposit ratio:
B20: Total accounts on ledger (excl. FX users) | C20: ='1. Customers'!$C$10+'1. Customers'!$C$11+'1. Customers'!$C$12+'1. Customers'!$C$13+'1. Customers'!$C$14+'1. Customers'!$C$15 | E20: Driver for core banking cost (£25/account)
B21: Total live credit facilities | C21: ='1. Customers'!$C$13+'1. Customers'!$C$14+'1. Customers'!$C$15 | E21: Driver for credit systems cost (£150/facility) and collections volume

Sheet 2. Revenues
B1: PRODUCT REVENUES — UNIT AND TOTAL
B2: Margins vs internal funds transfer prices. Stable deposits (BCA + instant savings) credited the liquidity-adjusted FTP; fixed deposits the term FTP less liquidity charge.
B4: Product | C4: Units | D4: Avg balance /unit | E4: Customer rate | F4: FTP rate | G4: Margin % | H4: NII per unit | I4: Fees per unit | J4: Revenue per unit | K4: Total NII (£) | L4: Total fees (£) | M4: Total revenue (£)
B5: Business current accounts | C5: ='1. Customers'!$C$10 | D5: ='1. Customers'!$D$10 | E5: ='Inputs'!$C$45 | F5: ='Inputs'!$C$13 | G5: =F5-E5 | H5: =D5*G5 | I5: =12*'Inputs'!$C$46+'Inputs'!$C$47 | J5: =H5+I5 | K5: =H5*C5 | L5: =I5*C5 | M5: =J5*C5
B6: Instant-access savings | C6: ='1. Customers'!$C$11 | D6: ='1. Customers'!$D$11 | E6: ='Inputs'!$C$48 | F6: ='Inputs'!$C$13 | G6: =F6-E6 | H6: =D6*G6 | I6: =0 | J6: =H6+I6 | K6: =H6*C6 | L6: =I6*C6 | M6: =J6*C6
B7: Fixed deposits (1yr) | C7: ='1. Customers'!$C$12 | D7: ='1. Customers'!$D$12 | E7: ='Inputs'!$C$49 | F7: ='Inputs'!$C$14 | G7: =F7-E7 | H7: =D7*G7 | I7: =0 | J7: =H7+I7 | K7: =H7*C7 | L7: =I7*C7 | M7: =J7*C7
B8: Business overdrafts | C8: ='1. Customers'!$C$13 | D8: ='1. Customers'!$D$13 | E8: ='Inputs'!$C$52 | F8: ='Inputs'!$C$8 | G8: =E8-F8 | H8: =D8*G8 | I8: ='Inputs'!$C$53*'Inputs'!$C$34 | J8: =H8+I8 | K8: =H8*C8 | L8: =I8*C8 | M8: =J8*C8
B9: Term loans | C9: ='1. Customers'!$C$14 | D9: ='1. Customers'!$D$14 | E9: ='Inputs'!$C$50 | F9: ='Inputs'!$C$9 | G9: =E9-F9 | H9: =D9*G9 | I9: ='Inputs'!$C$51*'Inputs'!$C$31/'Inputs'!$C$32 | J9: =H9+I9 | K9: =H9*C9 | L9: =I9*C9 | M9: =J9*C9
B10: Business credit cards | C10: ='1. Customers'!$C$15 | D10: ='1. Customers'!$D$15 | E10: ='Inputs'!$C$54 | F10: ='Inputs'!$C$8 | G10: =E10-F10 | H10: =D10*G10 | I10: ='Inputs'!$C$56*'Inputs'!$C$37*12+'Inputs'!$C$55 | J10: =H10+I10 | K10: =H10*C10 | L10: =I10*C10 | M10: =J10*C10
B11: Payments & FX | C11: ='1. Customers'!$C$16 | D11: ='1. Customers'!$D$16 | E11: =0 | F11: =0 | G11: =0 | H11: =D11*G11 | I11: ='Inputs'!$C$41*'Inputs'!$C$57+'Inputs'!$C$42*'Inputs'!$C$58 | J11: =H11+I11 | K11: =H11*C11 | L11: =I11*C11 | M11: =J11*C11
B12: TOTAL | K12: =SUM(K5:K11) | L12: =SUM(L5:L11) | M12: =SUM(M5:M11)
B14: Memo — liquidity charge inside deposit NII (deposits × buffer × drag): | D14: =-'1. Customers'!$E$17*'Inputs'!$C$10*'Inputs'!$C$11
B15: Memo — behavioural deposit credit inside deposit NII (stable balances × credit): | D15: =('1. Customers'!$E$10+'1. Customers'!$E$11)*'Inputs'!$C$12
B16: FINDING: fixed deposits at 4.30% vs term FTP net of liquidity charge earn a NEGATIVE margin — priced above their internal funding value.

Sheet 3. HR & Activity
B1: STEP 2 — RUNNING COSTS: PEOPLE FROM ACTIVITY DRIVERS
B2: Every FTE derived from transaction intensity (I) and customer load (L) — no headcount assumed directly. Every activity carries a named volume driver; no '% of revenue' ratios.
B4: Available hours per FTE per year | C4: ='Inputs'!$C$76*12 | E4: 150 hrs/month × 12
B5: Loaded hourly rate — credit analyst | C5: ='Inputs'!$C$78*(1+'Inputs'!$C$81)/'3. HR & Activity'!$C$4
B6: Loaded hourly rate — service & ops | C6: ='Inputs'!$C$79*(1+'Inputs'!$C$81)/'3. HR & Activity'!$C$4
B8: ACTIVITY DRIVER TABLE (transaction intensity, I)
B9: Activity | C9: Product | D9: Role | E9: Driver volume /yr | F9: Hours per | G9: Total hours /yr | H9: Cost (£/yr) | I9: Flow (tab 8) | J9: Cost low (£/yr) | K9: Cost high (£/yr)
B10: Customer onboarding (KYC/AML, setup) | C10: bca | D10: Service & ops | E10: ='1. Customers'!$C$6 | F10: ='Inputs'!$C$83 | G10: =E10*F10 | H10: =G10*'3. HR & Activity'!$C$6 | I10: CA-WP | J10: =H10*'Inputs'!$C$96 | K10: =H10*'Inputs'!$C$97
B11: Current account servicing | C11: bca | D11: Service & ops | E11: ='1. Customers'!$C$10 | F11: ='Inputs'!$C$84 | G11: =E11*F11 | H11: =G11*'3. HR & Activity'!$C$6 | I11: CA-WP | J11: =H11*'Inputs'!$C$96 | K11: =H11*'Inputs'!$C$97
B12: Instant savings servicing | C12: sav | D12: Service & ops | E12: ='1. Customers'!$C$11 | F12: ='Inputs'!$C$85 | G12: =E12*F12 | H12: =G12*'3. HR & Activity'!$C$6 | I12: SV-WP | J12: =H12*'Inputs'!$C$96 | K12: =H12*'Inputs'!$C$97
B13: Fixed deposit servicing | C13: dep | D13: Service & ops | E13: ='1. Customers'!$C$12 | F13: ='Inputs'!$C$86 | G13: =E13*F13 | H13: =G13*'3. HR & Activity'!$C$6 | I13: SV-WP | J13: =H13*'Inputs'!$C$96 | K13: =H13*'Inputs'!$C$97
B14: Overdraft reviews & renewals | C14: od | D14: Credit analyst | E14: ='1. Customers'!$C$13 | F14: ='Inputs'!$C$89 | G14: =E14*F14 | H14: =G14*'3. HR & Activity'!$C$5 | I14: LN-WP | J14: =H14*'Inputs'!$C$96 | K14: =H14*'Inputs'!$C$97
B15: Term loan underwriting (new loans) | C15: loan | D15: Credit analyst | E15: ='1. Customers'!$C$14/'Inputs'!$C$32 | F15: ='Inputs'!$C$87 | G15: =E15*F15 | H15: =G15*'3. HR & Activity'!$C$5 | I15: LN-WP | J15: =H15*'Inputs'!$C$96 | K15: =H15*'Inputs'!$C$97
B16: Term loan annual reviews | C16: loan | D16: Credit analyst | E16: ='1. Customers'!$C$14 | F16: ='Inputs'!$C$88 | G16: =E16*F16 | H16: =G16*'3. HR & Activity'!$C$5 | I16: LN-WP | J16: =H16*'Inputs'!$C$96 | K16: =H16*'Inputs'!$C$97
B17: Card servicing | C17: card | D17: Service & ops | E17: ='1. Customers'!$C$15 | F17: ='Inputs'!$C$90 | G17: =E17*F17 | H17: =G17*'3. HR & Activity'!$C$6 | I17: CC-WP | J17: =H17*'Inputs'!$C$96 | K17: =H17*'Inputs'!$C$97
B18: Payments & FX support | C18: fx | D18: Service & ops | E18: ='1. Customers'!$C$16 | F18: ='Inputs'!$C$91 | G18: =E18*F18 | H18: =G18*'3. HR & Activity'!$C$6 | I18: PX-WP | J18: =H18*'Inputs'!$C$96 | K18: =H18*'Inputs'!$C$97
B19: Collections — overdrafts | C19: od | D19: Credit analyst | E19: ='1. Customers'!$C$13*'Inputs'!$C$92 | F19: ='Inputs'!$C$93 | G19: =E19*F19 | H19: =G19*'3. HR & Activity'!$C$5 | I19: LN-WP | J19: =H19*'Inputs'!$C$96 | K19: =H19*'Inputs'!$C$97
B20: Collections — term loans | C20: loan | D20: Credit analyst | E20: ='1. Customers'!$C$14*'Inputs'!$C$92 | F20: ='Inputs'!$C$93 | G20: =E20*F20 | H20: =G20*'3. HR & Activity'!$C$5 | I20: LN-WP | J20: =H20*'Inputs'!$C$96 | K20: =H20*'Inputs'!$C$97
B21: Collections — cards | C21: card | D21: Credit analyst | E21: ='1. Customers'!$C$15*'Inputs'!$C$92 | F21: ='Inputs'!$C$93 | G21: =E21*F21 | H21: =G21*'3. HR & Activity'!$C$5 | I21: CC-WP | J21: =H21*'Inputs'!$C$96 | K21: =H21*'Inputs'!$C$97
B22: Collateral administration — term loans | C22: loan | D22: Credit analyst | E22: ='1. Customers'!$C$14 | F22: ='Inputs'!$C$94 | G22: =E22*F22 | H22: =G22*'3. HR & Activity'!$C$5 | I22: LN-WP | J22: =H22*'Inputs'!$C$96 | K22: =H22*'Inputs'!$C$97
B23: Recoveries & workout — term loans (banded input) | C23: loan | D23: Credit analyst | E23: ='1. Customers'!$C$14*'Inputs'!$C$92 | F23: ='Inputs'!$C$95 | G23: =E23*F23 | H23: =G23*'3. HR & Activity'!$C$5 | I23: LN-WP | J23: =H23*'Inputs'!$C$96 | K23: =H23*'Inputs'!$C$97
B25: FTE REQUIREMENT & COST (customer load, L)
B26: Role | D26: FTEs | E26: Salary (£) | H26: Total cost (£/yr)
B27: Relationship managers (portfolio-driven: 90 customers/RM) | D27: ='1. Customers'!$C$5/'Inputs'!$C$21 | E27: ='Inputs'!$C$77 | H27: =D27*E27*(1+'Inputs'!$C$81)
B28: Credit analysts (activity-driven) | D28: =SUMIF('3. HR & Activity'!$D$10:$D$23,"Credit analyst",'3. HR & Activity'!$G$10:$G$23)/'3. HR & Activity'!$C$4 | E28: ='Inputs'!$C$78 | H28: =D28*E28*(1+'Inputs'!$C$81)
B29: Service & operations (activity-driven) | D29: =SUMIF('3. HR & Activity'!$D$10:$D$23,"Service & ops",'3. HR & Activity'!$G$10:$G$23)/'3. HR & Activity'!$C$4 | E29: ='Inputs'!$C$79 | H29: =D29*E29*(1+'Inputs'!$C$81)
B30: Team managers (span-driven: 8 staff/manager) | D30: =('3. HR & Activity'!$D$27+'3. HR & Activity'!$D$28+'3. HR & Activity'!$D$29)/'Inputs'!$C$82 | E30: ='Inputs'!$C$80 | H30: =D30*E30*(1+'Inputs'!$C$81)
B31: TOTAL OPERATING-UNIT STAFF | D31: ='3. HR & Activity'!$D$27+'3. HR & Activity'!$D$28+'3. HR & Activity'!$D$29+'3. HR & Activity'!$D$30 | H31: ='3. HR & Activity'!$H$27+'3. HR & Activity'!$H$28+'3. HR & Activity'!$H$29+'3. HR & Activity'!$H$30
B33: THE RM SYSTEM — ORIGINATE / STEWARD / DEFEND (time-split is MISSING input #3: method default 50/30/20, banded)
B34: RM cost — originate | D34: ='Inputs'!$C$118 | H34: ='3. HR & Activity'!$H$27*'Inputs'!$C$118
B35: RM cost — steward | D35: ='Inputs'!$C$119 | H35: ='3. HR & Activity'!$H$27*'Inputs'!$C$119
B36: RM cost — defend | D36: ='Inputs'!$C$120 | H36: ='3. HR & Activity'!$H$27*'Inputs'!$C$120
B38: ORIGINATE — attributed per origination by relative effort
B39: Product | D39: Originations / renewals p.a. | E39: Effort weight | F39: Weighted volume | G39: RM cost attributed (£/yr) | H39: Cost per unit on book (£/yr)
B40: Term loans (new) | D40: ='1. Customers'!$C$14/'Inputs'!$C$32 | E40: ='Inputs'!$C$121 | F40: =D40*E40 | G40: =F40/SUM(F40:F41)*'3. HR & Activity'!$H$34 | H40: =G40/'1. Customers'!$C$14
B41: Overdrafts (annual renewals) | D41: ='1. Customers'!$C$13 | E41: ='Inputs'!$C$122 | F41: =D41*E41 | G41: =F41/SUM(F40:F41)*'3. HR & Activity'!$H$34 | H41: =G41/'1. Customers'!$C$13
B42: TOTAL RM ORIGINATION COST ATTRIBUTED | G42: =SUM(G40:G41)
B44: STEWARD — attributed to lending pro-rata balances (no PD benefit claimed: pd_red = 0, no evidence)
B45: Overdrafts | D45: ='1. Customers'!$E$13 | E45: ='1. Customers'!$E$13/('1. Customers'!$E$13+'1. Customers'!$E$14) | G45: =E45*'3. HR & Activity'!$H$35
B46: Term loans | D46: ='1. Customers'!$E$14 | E46: ='1. Customers'!$E$14/('1. Customers'!$E$13+'1. Customers'!$E$14) | G46: =E46*'3. HR & Activity'!$H$35
...

Sheet 4. Running Costs
B1: STEP 2 (CONT.) — TOTAL RUNNING COSTS OF THE OPERATING UNIT
B3: Unit HR cost (from HR & Activity sheet) | C3: ='3. HR & Activity'!$H$31
B4: Premises & facilities | C4: ='3. HR & Activity'!$D$31*'Inputs'!$C$100 | E4: FTEs × £5,500
B5: Depreciation | C5: ='3. HR & Activity'!$D$31*'Inputs'!$C$101 | E5: FTEs × £1,000
B6: Other direct running costs | C6: ='4. Running Costs'!$C$3*'Inputs'!$C$102 | E6: 5% of HR
B7: Unit platform | C7: ='1. Customers'!$C$4*'Inputs'!$C$103 | E7: £50/customer
B8: Fraud & APP losses | C8: ='Inputs'!$C$112*'1. Customers'!$C$10 | E8: Driver: current accounts (£38/BCA)
B9: FSCS deposit-protection levy | C9: ='1. Customers'!$E$17*'Inputs'!$C$114*'Inputs'!$C$113 | E9: 0.05% on 55% of deposit balances
B10: TOTAL DIRECT RUNNING COSTS | C10: ='4. Running Costs'!$C$3+'4. Running Costs'!$C$4+'4. Running Costs'!$C$5+'4. Running Costs'!$C$6+'4. Running Costs'!$C$7+'4. Running Costs'!$C$8+'4. Running Costs'!$C$9
B12: SHARE OF HEAD-OFFICE RUNNING COSTS
B13: HQ technology | C13: ='1. Customers'!$C$4*'Inputs'!$C$104 | E13: £380/customer
B14: HQ risk & compliance | C14: ='1. Customers'!$C$4*'Inputs'!$C$105 | E14: £210/customer
B15: HQ corporate centre | C15: ='1. Customers'!$C$4*'Inputs'!$C$106 | E15: £220/customer
B16: TOTAL HEAD-OFFICE ALLOCATION | C16: ='4. Running Costs'!$C$13+'4. Running Costs'!$C$14+'4. Running Costs'!$C$15
B18: Change-the-bank (portfolio hurdle — no product driver) | C18: ='1. Customers'!$C$4*'Inputs'!$C$115 | E18: £100/customer; held unallocated like joint costs
B19: TOTAL OPERATING COSTS | C19: ='4. Running Costs'!$C$10+'4. Running Costs'!$C$16+'4. Running Costs'!$C$18
B20: Operating cost per customer | C20: ='4. Running Costs'!$C$19/'1. Customers'!$C$4
B22: COST ATTRIBUTION MEMO (ABC to the causality limit)
B23: Activity-driven servicing cost (analyst + service payroll) | C23: ='3. HR & Activity'!$H$28+'3. HR & Activity'!$H$29
B24: Supervision & workplace pool (managers, premises, depreciation, other) | C24: ='3. HR & Activity'!$H$30+'4. Running Costs'!$C$4+'4. Running Costs'!$C$5+'4. Running Costs'!$C$6 | E24: Driver: staff time — follows each product's share of servicing + RM cost
B25: HQ tech attributed by driver (payments £100/BCA + core £25/acct + credit £150/facility) | C25: ='Inputs'!$C$109*'1. Customers'!$C$10+'Inputs'!$C$110*'1. Customers'!$C$20+'Inputs'!$C$111*'1. Customers'!$C$21
B26: HQ risk attributed by driver (KYC £120/new + refresh £50/customer) | C26: ='Inputs'!$C$107*'1. Customers'!$C$6+'Inputs'!$C$108*'1. Customers'!$C$4
B27: UNALLOCATED JOINT COSTS (no causal driver — brand, exec, finance, platform build) | C27: ='4. Running Costs'!$C$16-'4. Running Costs'!$C$25-'4. Running Costs'!$C$26 | E27: Held as a portfolio hurdle, not forced into products

Sheet 5. Risk & Capital
B1: STEP 3 — INVESTMENT COSTS: EXPECTED LOSSES, CAPITAL & REQUIRED RETURN
B3: EXPECTED CREDIT LOSSES
B4: Lending product | C4: Total balances (£) | D4: PD | E4: LGD | F4: Expected loss (£/yr) | G4: EL per unit (£)
B5: Business overdrafts | C5: ='1. Customers'!$E$13 | D5: ='Inputs'!$C$64 | E5: ='Inputs'!$C$65 | F5: =C5*D5*E5 | G5: =F5/'1. Customers'!$C$13
B6: Term loans | C6: ='1. Customers'!$E$14 | D6: ='Inputs'!$C$61 | E6: ='Inputs'!$C$62 | F6: =C6*D6*E6 | G6: =F6/'1. Customers'!$C$14
B7: Business credit cards | C7: ='1. Customers'!$E$15 | D7: ='Inputs'!$C$67 | E7: ='Inputs'!$C$68 | F7: =C7*D7*E7 | G7: =F7/'1. Customers'!$C$15
B8: TOTAL EXPECTED LOSSES | F8: =SUM(F5:F7)
B9: Gross PDs used unadjusted — no stewardship PD reduction claimed (pd_red = 0, no holdout evidence).
B11: CAPITAL & REQUIRED RETURN
B12: Credit risk-weighted assets | C12: ='1. Customers'!$E$13*'Inputs'!$C$66+'1. Customers'!$E$14*'Inputs'!$C$63+'1. Customers'!$E$15*'Inputs'!$C$69 | I12: Drawn balances × risk weights
B13: Operational risk-weighted assets | C13: ='2. Revenues'!$M$12*'Inputs'!$C$70 | I13: Gross income × 1.875 (fact pack)
B14: TOTAL RWAs | C14: ='5. Risk & Capital'!$C$12+'5. Risk & Capital'!$C$13
B15: Equity allocated (RWAs × 13.5% CET1) | C15: ='5. Risk & Capital'!$C$14*'Inputs'!$C$71
B16: Equity investment benefit (equity earns Bank Rate) | C16: ='5. Risk & Capital'!$C$15*'Inputs'!$C$6 | I16: Added to income in the P&L — equity funds assets so it earns the transfer price
B17: Required return on equity (equity × 11.5% CoE) | C17: ='5. Risk & Capital'!$C$15*'Inputs'!$C$72 | I17: The second-level investment cost: what shareholders must earn

Sheet 6. Unit Economics
B1: STEPS 4 & 5 — WHOLE-COST UNIT ECONOMICS BY PRODUCT
B2: Per account / facility / user per year. Whole cost = EL + servicing + RM + supervision + infrastructure + fraud + levies; economic contribution is after a charge for shareholder capital.
C4: Current accounts | D4: Instant savings | E4: Fixed deposits | F4: Overdrafts | G4: Term loans | H4: Credit cards | I4: Payments & FX | J4: TOTAL / blended
B5: (product key) | C5: bca | D5: sav | E5: dep | F5: od | G5: loan | H5: card | I5: fx
B6: Units (accounts / facilities / users) | C6: ='1. Customers'!$C$10 | D6: ='1. Customers'!$C$11 | E6: ='1. Customers'!$C$12 | F6: ='1. Customers'!$C$13 | G6: ='1. Customers'!$C$14 | H6: ='1. Customers'!$C$15 | I6: ='1. Customers'!$C$16 | J6: =SUM(C6:I6)
B7: Average balance per unit | C7: ='1. Customers'!$D$10 | D7: ='1. Customers'!$D$11 | E7: ='1. Customers'!$D$12 | F7: ='1. Customers'!$D$13 | G7: ='1. Customers'!$D$14 | H7: ='1. Customers'!$D$15 | I7: ='1. Customers'!$D$16
B8: Revenue per unit | C8: ='2. Revenues'!$J$5 | D8: ='2. Revenues'!$J$6 | E8: ='2. Revenues'!$J$7 | F8: ='2. Revenues'!$J$8 | G8: ='2. Revenues'!$J$9 | H8: ='2. Revenues'!$J$10 | I8: ='2. Revenues'!$J$11 | J8: ='2. Revenues'!$M$12/J6
B9: Expected credit loss per unit | C9: =0 | D9: =0 | E9: =0 | F9: ='5. Risk & Capital'!$F$5/'1. Customers'!$C$13 | G9: ='5. Risk & Capital'!$F$6/'1. Customers'!$C$14 | H9: ='5. Risk & Capital'!$F$7/'1. Customers'!$C$15 | I9: =0 | J9: ='5. Risk & Capital'!$F$8/J6
B10: Servicing cost per unit (activity-driven, tab 3) | C10: =SUMIF('3. HR & Activity'!$C$10:$C$23,C5,'3. HR & Activity'!$H$10:$H$23)/'1. Customers'!$C$10 | D10: =SUMIF('3. HR & Activity'!$C$10:$C$23,D5,'3. HR & Activity'!$H$10:$H$23)/'1. Customers'!$C$11 | E10: =SUMIF('3. HR & Activity'!$C$10:$C$23,E5,'3. HR & Activity'!$H$10:$H$23)/'1. Customers'!$C$12 | F10: =SUMIF('3. HR & Activity'!$C$10:$C$23,F5,'3. HR & Activity'!$H$10:$H$23)/'1. Customers'!$C$13 | G10: =SUMIF('3. HR & Activity'!$C$10:$C$23,G5,'3. HR & Activity'!$H$10:$H$23)/'1. Customers'!$C$14 | H10: =SUMIF('3. HR & Activity'!$C$10:$C$23,H5,'3. HR & Activity'!$H$10:$H$23)/'1. Customers'!$C$15 | I10: =SUMIF('3. HR & Activity'!$C$10:$C$23,I5,'3. HR & Activity'!$H$10:$H$23)/'1. Customers'!$C$16 | J10: ='4. Running Costs'!$C$23/J6
B11: RM origination (CAC) per unit | C11: =0 | D11: =0 | E11: =0 | F11: ='3. HR & Activity'!$G$41/'1. Customers'!$C$13 | G11: ='3. HR & Activity'!$G$40/'1. Customers'!$C$14 | H11: =0 | I11: =0 | J11: ='3. HR & Activity'!$H$34/J6
B12: RM stewardship per unit (pro-rata balances) | C12: =0 | D12: =0 | E12: =0 | F12: ='3. HR & Activity'!$G$45/'1. Customers'!$C$13 | G12: ='3. HR & Activity'!$G$46/'1. Customers'!$C$14 | H12: =0 | I12: =0 | J12: ='3. HR & Activity'!$H$35/J6
B13: Supervision & workplace per unit (driver: staff time) | C13: ='4. Running Costs'!$C$24*(SUMIF('3. HR & Activity'!$C$10:$C$23,C5,'3. HR & Activity'!$H$10:$H$23))/('4. Running Costs'!$C$23+'3. HR & Activity'!$H$34+'3. HR & Activity'!$H$35)/'1. Customers'!$C$10 | D13: ='4. Running Costs'!$C$24*(SUMIF('3. HR & Activity'!$C$10:$C$23,D5,'3. HR & Activity'!$H$10:$H$23))/('4. Running Costs'!$C$23+'3. HR & Activity'!$H$34+'3. HR & Activity'!$H$35)/'1. Customers'!$C$11 | E13: ='4. Running Costs'!$C$24*(SUMIF('3. HR & Activity'!$C$10:$C$23,E5,'3. HR & Activity'!$H$10:$H$23))/('4. Running Costs'!$C$23+'3. HR & Activity'!$H$34+'3. HR & Activity'!$H$35)/'1. Customers'!$C$12 | F13: ='4. Running Costs'!$C$24*(SUMIF('3. HR & Activity'!$C$10:$C$23,F5,'3. HR & Activity'!$H$10:$H$23)+'3. HR & Activity'!$G$41+'3. HR & Activity'!$G$45)/('4. Running Costs'!$C$23+'3. HR & Activity'!$H$34+'3. HR & Activity'!$H$35)/'1. Customers'!$C$13 | G13: ='4. Running Costs'!$C$24*(SUMIF('3. HR & Activity'!$C$10:$C$23,G5,'3. HR & Activity'!$H$10:$H$23)+'3. HR & Activity'!$G$40+'3. HR & Activity'!$G$46)/('4. Running Costs'!$C$23+'3. HR & Activity'!$H$34+'3. HR & Activity'!$H$35)/'1. Customers'!$C$14 | H13: ='4. Running Costs'!$C$24*(SUMIF('3. HR & Activity'!$C$10:$C$23,H5,'3. HR & Activity'!$H$10:$H$23))/('4. Running Costs'!$C$23+'3. HR & Activity'!$H$34+'3. HR & Activity'!$H$35)/'1. Customers'!$C$15 | I13: ='4. Running Costs'!$C$24*(SUMIF('3. HR & Activity'!$C$10:$C$23,I5,'3. HR & Activity'!$H$10:$H$23))/('4. Running Costs'!$C$23+'3. HR & Activity'!$H$34+'3. HR & Activity'!$H$35)/'1. Customers'!$C$16 | J13: ='4. Running Costs'!$C$24/J6
B14: Customer & account infrastructure per unit (driver-based) | C14: ='Inputs'!$C$103+'Inputs'!$C$110+'Inputs'!$C$109+'Inputs'!$C$108+'Inputs'!$C$107*'1. Customers'!$C$6/'1. Customers'!$C$10 | D14: ='Inputs'!$C$110 | E14: ='Inputs'!$C$110 | F14: ='Inputs'!$C$110+'Inputs'!$C$111 | G14: ='Inputs'!$C$110+'Inputs'!$C$111 | H14: ='Inputs'!$C$110+'Inputs'!$C$111 | I14: =0 | J14: =('4. Running Costs'!$C$7+'4. Running Costs'!$C$25+'4. Running Costs'!$C$26)/J6
B15: Fraud & APP losses per unit (driver: current accounts) | C15: ='Inputs'!$C$112 | D15: =0 | E15: =0 | F15: =0 | G15: =0 | H15: =0 | I15: =0 | J15: ='4. Running Costs'!$C$8/J6
B16: FSCS levy per unit (driver: protected deposits) | C16: ='1. Customers'!$D$10*'Inputs'!$C$114*'Inputs'!$C$113 | D16: ='1. Customers'!$D$11*'Inputs'!$C$114*'Inputs'!$C$113 | E16: ='1. Customers'!$D$12*'Inputs'!$C$114*'Inputs'!$C$113 | F16: =0 | G16: =0 | H16: =0 | I16: =0 | J16: ='4. Running Costs'!$C$9/J6
B17: ATTRIBUTABLE COST PER UNIT | C17: =C9+C10+C11+C12+C13+C14+C15+C16 | D17: =D9+D10+D11+D12+D13+D14+D15+D16 | E17: =E9+E10+E11+E12+E13+E14+E15+E16 | F17: =F9+F10+F11+F12+F13+F14+F15+F16 | G17: =G9+G10+G11+G12+G13+G14+G15+G16 | H17: =H9+H10+H11+H12+H13+H14+H15+H16 | I17: =I9+I10+I11+I12+I13+I14+I15+I16 | J17: =J9+J10+J11+J12+J13+J14+J15+J16
B18: CONTRIBUTION PER UNIT (revenue − attributable cost) | C18: =C8-C17 | D18: =D8-D17 | E18: =E8-E17 | F18: =F8-F17 | G18: =G8-G17 | H18: =H8-H17 | I18: =I8-I17 | J18: =J8-J17
B19: Allocated equity per unit (credit + op-risk RWA × 13.5%) | C19: ='Inputs'!$C$70*C8*'Inputs'!$C$71 | D19: ='Inputs'!$C$70*D8*'Inputs'!$C$71 | E19: ='Inputs'!$C$70*E8*'Inputs'!$C$71 | F19: =('1. Customers'!$D$13*'Inputs'!$C$66+'Inputs'!$C$70*F8)*'Inputs'!$C$71 | G19: =('1. Customers'!$D$14*'Inputs'!$C$63+'Inputs'!$C$70*G8)*'Inputs'!$C$71 | H19: =('1. Customers'!$D$15*'Inputs'!$C$69+'Inputs'!$C$70*H8)*'Inputs'!$C$71 | I19: ='Inputs'!$C$70*I8*'Inputs'!$C$71
B20: Net capital charge per unit (equity × (CoE − Bank Rate)) | C20: =C19*('Inputs'!$C$72-'Inputs'!$C$6) | D20: =D19*('Inputs'!$C$72-'Inputs'!$C$6) | E20: =E19*('Inputs'!$C$72-'Inputs'!$C$6) | F20: =F19*('Inputs'!$C$72-'Inputs'!$C$6) | G20: =G19*('Inputs'!$C$72-'Inputs'!$C$6) | H20: =H19*('Inputs'!$C$72-'Inputs'!$C$6) | I20: =I19*('Inputs'!$C$72-'Inputs'!$C$6)
B21: ECONOMIC CONTRIBUTION PER UNIT (pre-tax, before joint costs) | C21: =C18-C20 | D21: =D18-D20 | E21: =E18-E20 | F21: =F18-F20 | G21: =G18-G20 | H21: =H18-H20 | I21: =I18-I20
B22: Economic contribution margin (% of revenue; n/m if revenue ≤ 0) | C22: =IF(C8<=0,"n/m",C21/C8) | D22: =IF(D8<=0,"n/m",D21/D8) | E22: =IF(E8<=0,"n/m",E21/E8) | F22: =IF(F8<=0,"n/m",F21/F8) | G22: =IF(G8<=0,"n/m",G21/G8) | H22: =IF(H8<=0,"n/m",H21/H8) | I22: =IF(I8<=0,"n/m",I21/I8)
B23: Total contribution (£/yr) | C23: =C18*C6 | D23: =D18*D6 | E23: =E18*E6 | F23: =F18*F6 | G23: =G18*G6 | H23: =H18*H6 | I23: =I18*I6 | J23: =SUM(C23:I23)
B24: Total economic contribution (£/yr) | C24: =C21*C6 | D24: =D21*D6 | E24: =E21*E6 | F24: =F21*F6 | G24: =G21*G6 | H24: =H21*H6 | I24: =I21*I6 | J24: =SUM(C24:I24)
B26: BRIDGE TO THE UNIT P&L
B27: Total contribution across products | C27: =J23
B28: Less: RM defence (retention spend held at centre level) | C28: =-'3. HR & Activity'!$H$36
B29: Less: unallocated joint costs (no causal driver) | C29: =-'4. Running Costs'!$C$27
B30: Less: change-the-bank (portfolio hurdle) | C30: =-'4. Running Costs'!$C$18
B31: Operating profit before capital charges | C31: =C27+C28+C29+C30
B32: Check vs P&L (income excl. equity benefit − EL − opex) — should be zero | C32: =C31-('2. Revenues'!$M$12-'5. Risk & Capital'!$F$8-'4. Running Costs'!$C$19) | D32: ✓ must tie to ~0

Sheet 7. P&L
B1: STEP 5 — WHOLE-COST P&L: MERIDIAN BUSINESS BANKING AT STEADY STATE
B3: Net interest income (vs funds transfer price) | C3: ='2. Revenues'!$K$12
B4: Fee & commission income | C4: ='2. Revenues'!$L$12
B5: Equity investment benefit | C5: ='5. Risk & Capital'!$C$16 | E5: Allocated equity earning Bank Rate
B6: TOTAL OPERATING INCOME | C6: ='7. P&L'!$C$3+'7. P&L'!$C$4+'7. P&L'!$C$5
B7: Expected credit losses | C7: =-'5. Risk & Capital'!$F$8
B8: NET OPERATING INCOME | C8: ='7. P&L'!$C$6+'7. P&L'!$C$7
B9: Staff costs (unit) | C9: =-'4. Running Costs'!$C$3
B10: Premises & depreciation | C10: =-'4. Running Costs'!$C$4-'4. Running Costs'!$C$5
B11: Other direct costs & unit platform | C11: =-'4. Running Costs'!$C$6-'4. Running Costs'!$C$7
B12: Fraud & payment losses (incl. APP reimbursement) | C12: =-'4. Running Costs'!$C$8
B13: FSCS deposit-protection levy | C13: =-'4. Running Costs'!$C$9
B14: Share of head-office costs | C14: =-'4. Running Costs'!$C$16
B15: Change-the-bank / transformation | C15: =-'4. Running Costs'!$C$18 | E15: Portfolio hurdle — not attributed to products
B16: TOTAL OPERATING COSTS | C16: ='7. P&L'!$C$9+'7. P&L'!$C$10+'7. P&L'!$C$11+'7. P&L'!$C$12+'7. P&L'!$C$13+'7. P&L'!$C$14+'7. P&L'!$C$15
B17: PROFIT BEFORE TAX | C17: ='7. P&L'!$C$8+'7. P&L'!$C$16
B18: Tax (28%) | C18: =-'7. P&L'!$C$17*'Inputs'!$C$73
B19: PROFIT AFTER TAX | C19: ='7. P&L'!$C$17+'7. P&L'!$C$18
B20: Required return on allocated equity | C20: =-'5. Risk & Capital'!$C$17 | E20: Second-level investment cost: what shareholders must earn (11.5% CoE)
B21: ECONOMIC PROFIT (value created above cost of equity) | C21: ='7. P&L'!$C$19+'7. P&L'!$C$20
B23: KEY RATIOS
B24: Customers | C24: ='1. Customers'!$C$4
B25: Revenue per customer | C25: ='7. P&L'!$C$6/'1. Customers'!$C$4
B26: Operating cost per customer | C26: =-'7. P&L'!$C$16/'1. Customers'!$C$4
B27: Cost:income ratio | C27: =-'7. P&L'!$C$16/'7. P&L'!$C$6
B28: Cost of risk (EL / lending balances) | C28: =-'7. P&L'!$C$7/'1. Customers'!$E$18
B29: Return on allocated equity (RoE) | C29: ='7. P&L'!$C$19/'5. Risk & Capital'!$C$15 | E29: Compare to the 11.5% cost of equity — below it, the unit destroys value
B30: Loan-to-deposit ratio | C30: ='1. Customers'!$E$18/'1. Customers'!$E$17
B32: MISSING-INPUT BANDS — PRE-TAX P&L SWING (flag-and-band, never silently invented)
B33: Flagged input | C33: Swing low→high (£/yr pre-tax) | E33: How it enters
B34: MISSING #1 — card interchange rate [1.65%, 1.90%] | C34: =('Inputs'!$F$56-'Inputs'!$E$56)*'Inputs'!$C$37*12*'1. Customers'!$C$15 | E34: Fee revenue on card spend; central 1.775% used in the model
B35: MISSING #2 — workout hours/case [4, 12] | C35: =('Inputs'!$F$95-'Inputs'!$E$95)*'1. Customers'!$C$14*'Inputs'!$C$92*'3. HR & Activity'!$C$5 | E35: Analyst cost on defaulted term loans; central 8h used
B36: MISSING #3 — RM time-split originate [40%, 60%] | C36: 0 | E36: Attribution-only: moves RM cost BETWEEN products (loan CAC vs OD renewal cost); total P&L unchanged. Central 50/30/20 used.
B37: GAP FOUND — BCA credit interest [0%, 0.5%] | C37: =('Inputs'!$F$45-'Inputs'!$E$45)*'1. Customers'!$E$10 | E37: Interest cost on £630m of BCA balances; 0% assumed
B38: GAP FOUND — FX conversion margin [0.25%, 1.5%] | C38: =('Inputs'!$F$57-'Inputs'!$E$57)*'Inputs'!$C$41*'1. Customers'!$C$16 | E38: FX revenue on ~£405m conversion volume; 0.75% assumed — the widest band in the model

Sheet 8. Flow Register
B1: FLOW REGISTER — PORTFOLIO OF 4-D PRODUCTS ON A SHARED PLATFORM
B2: One row per flow. Each product's working product is DERIVED from its CTM state change (meridian_ctm.md); the shared platform serves every product. Partners are pass-through waypoints; the three boundary actors always appear.
B4: Flow | C4: Product | D4: Type | E4: Category | F4: Name | G4: State change driven (from CTM) | H4: Direction | I4: Medium | J4: Direct producer | K4: DRI (single accountable owner)
B5: CP1 | C5: Shared platform | D5: CP | E5: Comms | F5: Marketing & brand | G5: — | H5: HQ->cust | I5: digital | J5: Marketing | K5: Head of Marketing
B6: CA-WP | C6: Current account | D6: WP | E6: Core | F6: Hold & use day-to-day money | G6: Money mixed & ad hoc -> held safe, usable on demand | H6: HQ->cust | I6: digital | J6: Service & ops | K6: Head of Business Current Accounts
B7: CA-PP1 | C7: Current account | D7: PP | E7: Money | F7: Account fees & txn income | G7: — | H7: cust->HQ | I7: digital | J7: Payments ops | K7: Head of Business Current Accounts
B8: SV-WP | C8: Savings & deposits | D8: WP | E8: Core | F8: Interest-earning safe store (instant + 1yr fixed) | G8: Surplus idle -> surplus earning | H8: HQ->cust | I8: digital | J8: Service & ops | K8: Head of Deposits
B9: SV-PP1 | C9: Savings & deposits | D9: PP | E9: Money | F9: Deposits placed | G9: — | H9: cust->HQ | I9: digital | J9: Treasury | K9: Treasurer
B10: SV-PP2 | C10: Savings & deposits | D10: PP | E10: Money | F10: Interest paid | G10: — | H10: HQ->cust | I10: digital | J10: Treasury | K10: Treasurer
B11: LN-WP | C11: Lending & credit | D11: WP | E11: Core | F11: Credit facility (term loan · overdraft) | G11: Opportunity unfundable -> funded | H11: HQ->cust | I11: physical | J11: RM · Credit analyst | K11: Credit Director
B12: LN-PP1 | C12: Lending & credit | D12: PP | E12: Money | F12: Drawdown | G12: — | H12: HQ->cust | I12: digital | J12: Treasury | K12: Treasurer
B13: LN-PP2 | C13: Lending & credit | D13: PP | E13: Money | F13: Repayments & interest | G13: — | H13: cust->HQ | I13: digital | J13: Payments ops | K13: Head of Payments & FX
B14: CC-WP | C14: Business credit card | D14: WP | E14: Core | F14: Revolving credit line | G14: Spend blocked by cash timing -> enabled on credit | H14: HQ->cust | I14: digital | J14: Service & ops | K14: Head of Cards
B15: CC-PP1 | C15: Business credit card | D15: PP | E15: Money | F15: Spend settled | G15: — | H15: HQ->cust | I15: digital | J15: Payments ops | K15: Head of Cards
... B34: I3 | C34: Bank boundary | D34: Info | E34: Info-out | F34: Open Banking data to TPPs (via E3) | G34: — | H34: HQ->TPPs | I34: digital | J34: Digital · IT | K34: Head of Digital
B36: PER-FLOW COSTED ACTIVITIES — activity cost per flow with [low, high] band
B37: Flow | C37: Activity cost (£/yr) | D37: Low (£/yr) | E37: High (£/yr) | F37: Costed via
B38: CP1 | C38: =SUMIF('3. HR & Activity'!$I$10:$I$23,"CP1",'3. HR & Activity'!$H$10:$H$23) | D38: =SUMIF('3. HR & Activity'!$I$10:$I$23,"CP1",'3. HR & Activity'!$J$10:$J$23) | E38: =SUMIF('3. HR & Activity'!$I$10:$I$23,"CP1",'3. HR & Activity'!$K$10:$K$23) | F38: HQ corporate-centre pool — no activity rows; pool-costed
B39: CA-WP | C39: =SUMIF('3. HR & Activity'!$I$10:$I$23,"CA-WP",'3. HR & Activity'!$H$10:$H$23) | D39: =SUMIF('3. HR & Activity'!$I$10:$I$23,"CA-WP",'3. HR & Activity'!$J$10:$J$23) | E39: =SUMIF('3. HR & Activity'!$I$10:$I$23,"CA-WP",'3. HR & Activity'!$K$10:$K$23) | F39: Activity rows (onboarding · BCA servicing) + per-account infrastructure drivers
B40: SV-WP | C40: =SUMIF('3. HR & Activity'!$I$10:$I$23,"SV-WP",'3. HR & Activity'!$H$10:$H$23) | D40: =SUMIF('3. HR & Activity'!$I$10:$I$23,"SV-WP",'3. HR & Activity'!$J$10:$J$23) | E40: =SUMIF('3. HR & Activity'!$I$10:$I$23,"SV-WP",'3. HR & Activity'!$K$10:$K$23) | F40: Activity rows (savings & fixed deposit servicing)
B41: LN-WP | C41: =SUMIF('3. HR & Activity'!$I$10:$I$23,"LN-WP",'3. HR & Activity'!$H$10:$H$23) | D41: =SUMIF('3. HR & Activity'!$I$10:$I$23,"LN-WP",'3. HR & Activity'!$J$10:$J$23) | E41: =SUMIF('3. HR & Activity'!$I$10:$I$23,"LN-WP",'3. HR & Activity'!$K$10:$K$23) | F41: Activity rows (underwriting · reviews · renewals · collections · collateral · workout) + RM originate/steward
B42: CC-WP | C42: =SUMIF('3. HR & Activity'!$I$10:$I$23,"CC-WP",'3. HR & Activity'!$H$10:$H$23) | D42: =SUMIF('3. HR & Activity'!$I$10:$I$23,"CC-WP",'3. HR & Activity'!$J$10:$J$23) | E42: =SUMIF('3. HR & Activity'!$I$10:$I$23,"CC-WP",'3. HR & Activity'!$K$10:$K$23) | F42: Activity rows (card servicing · card collections) + credit systems driver
B43: PX-WP | C43: =SUMIF('3. HR & Activity'!$I$10:$I$23,"PX-WP",'3. HR & Activity'!$H$10:$H$23) | D43: =SUMIF('3. HR & Activity'!$I$10:$I$23,"PX-WP",'3. HR & Activity'!$J$10:$J$23) | E43: =SUMIF('3. HR & Activity'!$I$10:$I$23,"PX-WP",'3. HR & Activity'!$K$10:$K$23) | F43: Activity rows (payments & FX support) + payments processing driver
B44: E1 | C44: =SUMIF('3. HR & Activity'!$I$10:$I$23,"E1",'3. HR & Activity'!$H$10:$H$23) | D44: =SUMIF('3. HR & Activity'!$I$10:$I$23,"E1",'3. HR & Activity'!$J$10:$J$23) | E44: =SUMIF('3. HR & Activity'!$I$10:$I$23,"E1",'3. HR & Activity'!$K$10:$K$23) | F44: Unit platform £50/customer + HQ tech pool — no activity rows
B45: S4 | C45: =SUMIF('3. HR & Activity'!$I$10:$I$23,"S4",'3. HR & Activity'!$H$10:$H$23) | D45: =SUMIF('3. HR & Activity'!$I$10:$I$23,"S4",'3. HR & Activity'!$J$10:$J$23) | E45: =SUMIF('3. HR & Activity'!$I$10:$I$23,"S4",'3. HR & Activity'!$K$10:$K$23) | F45: HQ risk pool + fraud loss line (P&L); reimbursement outflow in fidelity table
B46: PartP3 | C46: =SUMIF('3. HR & Activity'!$I$10:$I$23,"PartP3",'3. HR & Activity'!$H$10:$H$23) | D46: =SUMIF('3. HR & Activity'!$I$10:$I$23,"PartP3",'3. HR & Activity'!$J$10:$J$23) | E46: =SUMIF('3. HR & Activity'!$I$10:$I$23,"PartP3",'3. HR & Activity'!$K$10:$K$23) | F46: ALL front-line salary cost = the activity rows themselves; HQ salaries in HQ pools
B47: PartP4 | C47: =SUMIF('3. HR & Activity'!$I$10:$I$23,"PartP4",'3. HR & Activity'!$H$10:$H$23) | D47: =SUMIF('3. HR & Activity'!$I$10:$I$23,"PartP4",'3. HR & Activity'!$J$10:$J$23) | E47: =SUMIF('3. HR & Activity'!$I$10:$I$23,"PartP4",'3. HR & Activity'!$K$10:$K$23) | F47: Premises · depreciation · other · tech vendor lines (tab 4)
B48: CHECK — activity costs fully allocated to flows | C48: =SUMPRODUCT(('3. HR & Activity'!$I$10:$I$23<>"")*'3. HR & Activity'!$H$10:$H$23)-('4. Running Costs'!$C$23) | F48: tagged activity cost minus analyst & service payroll → 0
B50: BANK-BOUNDARY FIDELITY CHECK — every P&L money outflow ties to a flow
B51: P&L outflow | C51: Carried by flow | D51: Status
B52: Deposit interest paid (3.20% / 4.30%) | C52: SV-PP2 | D52: ✓
B53: Wholesale funding & liquidity-buffer give-up (inside FTP) | C53: PartP1 — BoE / markets | D53: ✓
B54: Staff salaries & benefits | C54: PartP3 — Employees | D54: ✓
B55: Premises · depreciation · other · tech & vendors | C55: PartP4 — Suppliers | D55: ✓
B56: Fraud & APP reimbursement to customers | C56: S4 outflow | D56: ✓
B57: FSCS levy | C57: PartP1 — FSCS | D57: ✓
B58: Card scheme fees | C58: CC-PP1 (inside tech pool) | D58: ✓
B59: Change-the-bank spend | C59: PartP4 — Suppliers (portfolio hurdle) | D59: ✓
B60: Tax (28%) | C60: PartP1 — HMRC | D60: ✓
B61: Dividends / required return on equity | C61: PartP2 — Shareholders | D61: ✓
...
