Workbook

Sheet Guide
B1: UK SME BANK — BOTTOM-UP UNIT ECONOMICS MODEL
B2: MODEL VERSION: v1.7 · 22 August 2026 — check github.com/tmth-studio/sme-bank-models for the latest; the version history below tells you what changed since your download.
B4: Version history
B5: • v1.7 (22 Aug 2026) — operational leverage. Every cost line in the model scaled linearly with its driver, which forces a cost elasticity of exactly 1.0 and makes cost per customer flat at every scale. Allica Bank's own accounts put that elasticity at 0.808 across 2022-23 and 0.622 across 2023-24 — cost rises materially more slowly than the book. Inputs section O adds a cost scale elasticity and the customer count the per-customer rates are calibrated at; the head-office pools, the platform line and change-the-bank now scale by it. Default 1.0 reproduces v1.6 exactly. Tab 11 adds the out-of-sample test that measured it.
B6: • v1.6 (22 Aug 2026) — validation and drivers. Tab 10 ELASTICITIES: every input bumped +1% and the workbook recalculated, giving the % change in PBT, cost:income, RoE and income. Only one input has an elasticity above 1 on profit — the term loan customer rate, at +1.25; reachable market and penetration are exactly +1.00 (pure scale); nothing else exceeds 0.53. Tab 11 BACKTEST against Allica Bank FY2023 audited accounts: the revenue engine reproduces a real bank's operating income to within 8%, and the cost engine under-predicts by 7x. Diagnosis: head-office cost was modelled purely per customer, which is a scale assumption disguised as a driver. Inputs section N therefore adds a fixed component to each head-office pool, defaulting to 0 so v1.5 results are unchanged.
B7: • v1.5 (22 Aug 2026) — PROCESS LAYER on the Step 2 tabs. Tab 3 gains process columns M-T (process type, yield, attempts, automation, best-in-class intensity and yield, benchmark source, £ gap) and a HEAD-OFFICE PROCESS REGISTER of 22 processes already named in the tab 9 operational model but never costed. Yield inflates ATTEMPTS and never deflates outcomes — that is what stops it double-counting with the CEP layer's demand-side conversion. Head-office costs are carved OUT of the pools, so naming a process moves money from unallocated to attributed and the total never changes. New sheet 3b indexes every process to the numbers it moves, and imputes what each would have to become to hit a target cost:income. Mode OFF (default) = results identical to v1.4.
B8: • v1.4 (22 Aug 2026) — CEP DEMAND LAYER. New sheet 1b derives the nine product penetrations and the customer count instead of asserting them: penetration = (lambda*c x L) / (1 + lambda*c x L), where lambda*c = category-entry-point events x presence x conversion and L is the holding life. Little's Law run forwards; no time axis is added and the model stays a steady-state snapshot. Ships deliberately EMPTY — every event/presence/conversion cell is blank and carries the cohort query that fills it, and any unpopulated product falls back to its hardcoded penetration. Mode OFF (default) = results identical to v1.3; CALIBRATE reports the won-event rate implied by today's assumptions and changes nothing.
B9: • v1.3 (21 Aug 2026) — churn replacement is a costed activity end-to-end: new input cac_new (£240 acquisition marketing per new customer won, carved out of the corporate-centre pool — hq_oh £250→£222); driver-linked on tab 4, attributed to the current account (gateway product) on tab 6; 'value of preventing one churn' memo added to tab 6. Raising the churn input now inflates demand-generation cost, not just processing. Central PBT shifts <£1k/unit (carve-out rounding).
B10: • v1.2.1 (21 Aug 2026) — documentation only: added 'What period this models' to this Guide (steady-state annual snapshot, stationary book, churn replacement costed, transitions out of scope). No formula or input changes — results identical to v1.2.
B11: • v1.2 (12 Aug 2026) — ranges, not points: every input carries Pessimistic/Central/Optimistic (direction-aware) with one scenario toggle driving the ACTIVE column; bands seeded only where benchmark evidence exists (BoE loan rates, Jefferies CoE, peer CET1, BoE SME PD, best-buy savings). Central results identical to v1.1.
B12: • v1.1 (12 Aug 2026) — scenario-building granularity: Channel tag (digital-amenable/judgement) on every activity row (tab 3); per-product RM-held share inputs + RM/digital unit split columns (tab 1). Economics unchanged — tie-out and all product margins identical to v1.0.
B13: • v1.0 (10 Aug 2026) — first published version: 9 tabs + flow register, FTP with liquidity/behavioural terms, fraud/FSCS/change-the-bank lines, segment-pod LMUs, bridge check.
... B48: • The FTP now carries an explicit liquidity charge (buffer × drag) and a behavioural credit for stable deposits, shown as memos on the Revenues tab; it is still a single curve, not a full behavioural-maturity model. Fraud & payment losses, the FSCS levy, collateral administration & recoveries, and change-the-bank spend are now modelled explicitly. Operational-risk RWA is proxied at 15% of gross income; head-office and change costs are allocated per customer.

Sheet Inputs
B1: INPUTS & ASSUMPTIONS — UK SME BANK BOTTOM-UP MODEL
B2: Edit blue cells. Yellow = highest-impact levers. RANGES: every input carries Pessimistic (D) / Central (C) / Optimistic (E) — direction-aware, not numeric low/high; the model runs on ACTIVE (F) via the scenario toggle. Bands are seeded only where benchmark evidence exists; when adapting with your own data, record your uncertainty in D/E rather than flattening to a point.
B4: SCENARIO TOGGLE (1 = pessimistic · 2 = central · 3 = optimistic) | C4: 2
B6: A. MARKET & FUNDING RATES
B7: Item | C7: Central | D7: Pessimistic | E7: Optimistic | F7: ACTIVE | G7: Unit | H7: Source / note
B8: Bank of England Bank Rate | C8: 0.0375 | D8: 0.0375 | E8: 0.0375 | F8: =CHOOSE('Inputs'!$C$4,D8,C8,E8) | G8: % p.a. | H8: BoE Bank Rate held at 3.75%, July 2026 (bankofengland.co.uk; moneysavingexpert.com)
B9: Term funding premium over Bank Rate | C9: 0.006 | D9: 0.006 | E9: 0.006 | F9: =CHOOSE('Inputs'!$C$4,D9,C9,E9) | G9: % p.a. | H9: Assumption: cost of term funding above base — 1yr fixed business deposits pay 4.2–4.6% vs base 3.75% (businessexpert.co.uk, Jul 2026)
B10: Funds transfer price — floating (= Bank Rate) | C10: ='Inputs'!$F$8 | F10: =C10 | G10: % p.a. | H10: Internal transfer price credited to deposits / charged to floating lending
B11: Funds transfer price — term (= Bank Rate + premium) | C11: ='Inputs'!$F$8+'Inputs'!$F$9 | F11: =C11 | G11: % p.a. | H11: Charged to term/fixed-rate lending; credited to term deposits
B12: A2. LIQUIDITY & FUNDING (explicit FTP: liquidity charge + behavioural deposit credit)
B13: Item | C13: Central | D13: Pessimistic | E13: Optimistic | F13: ACTIVE | G13: Unit | H13: Source / note
B14: Liquidity buffer held against deposits (LCR / HQLA) | C14: 0.15 | D14: 0.15 | E14: 0.15 | F14: =CHOOSE('Inputs'!$C$4,D14,C14,E14) | G14: % of deposits | H14: Assumption: high-quality liquid assets held against deposit-outflow risk
B15: Yield give-up on the liquidity buffer vs Bank Rate | C15: 0.01 | D15: 0.01 | E15: 0.01 | F15: =CHOOSE('Inputs'!$C$4,D15,C15,E15) | G15: % p.a. | H15: Assumption: HQLA (gilts, central-bank reserves) yield below Bank Rate — the cost of holding the buffer
B16: Behavioural term credit for stable non-maturing deposits | C16: 0.005 | D16: 0.005 | E16: 0.005 | F16: =CHOOSE('Inputs'!$C$4,D16,C16,E16) | G16: % p.a. | H16: Assumption: sticky current-account and savings balances behave long, so earn a term uplift over the float FTP
B17: FTP credited to stable deposits (float − liquidity charge + behavioural credit) | C17: ='Inputs'!$F$10-'Inputs'!$F$14*'Inputs'!$F$15+'Inputs'!$F$16 | F17: =C17 | G17: % p.a. | H17: Applied to current accounts and instant savings — makes the deposit-funding value explicit
B18: FTP credited to term deposits (term − liquidity charge) | C18: ='Inputs'!$F$11-'Inputs'!$F$14*'Inputs'!$F$15 | F18: =C18 | G18: % p.a. | H18: Applied to notice & fixed deposits (already termed; no behavioural uplift)
B19: B. OPERATING UNIT — REGIONAL BUSINESS CENTRE (Simanis Step 1: bounding)
B20: Item | C20: Central | D20: Pessimistic | E20: Optimistic | F20: ACTIVE | G20: Unit | H20: Source / note
B21: Reachable SMEs in region (R) | C21: 18750 | D21: 18750 | E21: 18750 | F21: =CHOOSE('Inputs'!$C$4,D21,C21,E21) | G21: businesses | H21: Catchment per centre: UK's ~5.6m businesses (DBT Business Population Estimates) ÷ 300 centres of national coverage
B22: Steady-state penetration (P) | C22: 0.16 | D22: 0.16 | E22: 0.16 | F22: =CHOOSE('Inputs'!$C$4,D22,C22,E22) | G22: % of reachable | H22: Set so 300 centres × 3,000 customers = 900,000 BCA customers — a ~16% national SME market share, i.e. big-4 incumbent territory (Barclays/Lloyds each serve ~1m+ business customers)
B23: Annual customer churn (replaced at steady state) | C23: 0.12 | D23: 0.12 | E23: 0.12 | F23: =CHOOSE('Inputs'!$C$4,D23,C23,E23) | G23: % p.a. | H23: Assumption: SME banking attrition; drives onboarding workload
B24: Share of customers that are relationship-managed | C24: 0.15 | D24: 0.15 | E24: 0.15 | F24: =CHOOSE('Inputs'!$C$4,D24,C24,E24) | G24: % | H24: SEGMENT BOUNDARY: larger SMEs (by turnover/complexity) get a named RM; the small-business mass is served digitally
B25: Customers per relationship manager (L) | C25: 120 | D25: 120 | E25: 120 | F25: =CHOOSE('Inputs'!$C$4,D25,C25,E25) | G25: customers | H25: Assumption: RM portfolio size (customer load)
B26: RMs per relationship pod | C26: 6 | D26: 6 | E26: 6 | F26: =CHOOSE('Inputs'!$C$4,D26,C26,E26) | G26: RMs | H26: Segment-bounded LMU: a relationship pod = pod lead + RMs + analysts; capacity = RMs × portfolio
B27: Service & ops FTE per digital service pod | C27: 10 | D27: 10 | E27: 10 | F27: =CHOOSE('Inputs'!$C$4,D27,C27,E27) | G27: FTE | H27: Segment-bounded LMU: a digital pod serves the small-business segment via app + contact centre
B28: C. PRODUCT HOLDINGS & BALANCES (per customer)
B29: Item | C29: Central | D29: Pessimistic | E29: Optimistic | F29: ACTIVE | G29: Unit | H29: Source / note
B30: Business current account — penetration | C30: 1 | D30: 1 | E30: 1 | F30: =CHOOSE('Inputs'!$C$4,D30,C30,E30) | G30: % of customers | H30: Anchor product: every customer holds a BCA
B31: BCA — average credit balance | C31: 18000 | D31: 14000 | E31: 22000 | F31: =CHOOSE('Inputs'!$C$4,D31,C31,E31) | G31: £/account | H31: Assumption — NO public benchmark exists (top internal-validation item); wide band reflects that
B32: Instant-access savings — penetration | C32: 0.4 | D32: 0.4 | E32: 0.4 | F32: =CHOOSE('Inputs'!$C$4,D32,C32,E32) | G32: % | H32: Assumption
B33: Instant-access savings — average balance | C33: 30000 | D33: 30000 | E33: 30000 | F33: =CHOOSE('Inputs'!$C$4,D33,C33,E33) | G33: £/account | H33: Assumption
B34: Notice & fixed deposits — penetration | C34: 0.15 | D34: 0.15 | E34: 0.15 | F34: =CHOOSE('Inputs'!$C$4,D34,C34,E34) | G34: % | H34: Assumption
B35: Notice & fixed deposits — average balance | C35: 75000 | D35: 75000 | E35: 75000 | F35: =CHOOSE('Inputs'!$C$4,D35,C35,E35) | G35: £/account | H35: Assumption
B36: Overdraft — penetration | C36: 0.25 | D36: 0.25 | E36: 0.25 | F36: =CHOOSE('Inputs'!$C$4,D36,C36,E36) | G36: % | H36: Assumption: share of customers with a facility
B37: Overdraft — average limit | C37: 15000 | D37: 15000 | E37: 15000 | F37: =CHOOSE('Inputs'!$C$4,D37,C37,E37) | G37: £/facility | H37: Assumption
B38: Overdraft — average utilisation | C38: 0.45 | D38: 0.45 | E38: 0.45 | F38: =CHOOSE('Inputs'!$C$4,D38,C38,E38) | G38: % of limit | H38: Assumption
B39: Term loans / commercial mortgages — penetration | C39: 0.12 | D39: 0.12 | E39: 0.12 | F39: =CHOOSE('Inputs'!$C$4,D39,C39,E39) | G39: % | H39: Assumption
B40: Term loans — average balance | C40: 250000 | D40: 250000 | E40: 250000 | F40: =CHOOSE('Inputs'!$C$4,D40,C40,E40) | G40: £/loan | H40: Assumption
B41: Term loans — average life | C41: 4 | D41: 4 | E41: 4 | F41: =CHOOSE('Inputs'!$C$4,D41,C41,E41) | G41: years | H41: Assumption: drives origination volume & fee amortisation
... B55: International payments — number per user per year | C55: 30 | D55: 30 | E55: 30 | F55: =CHOOSE('Inputs'!$C$4,D55,C55,E55) | G55: payments | H55: Assumption
...

Sheet 1. Customers
B1: STEP 1 — BOUNDING THE OPERATING UNIT
B2: SME banks organise by CUSTOMER SEGMENT, not geography (Simanis: digital offerings bound the LMU by 'a defined customer segment'). The operational LMUs are segment pods — relationship pods and digital service pods (Org tab, 'Segment pods'). This tab models a 1/300 slice of the national book purely for unit economics; the slice is a modelling construct, not the operating unit.
B4: Customers at steady state | C4: ='1b. Demand & CEPs'!$G$21 | E4: CEP layer OFF/CALIBRATE → reachable market × steady-state penetration. LIVE → derived from acquisition CEPs (sheet 1b).
B5: …of which relationship-managed | C5: ='1. Customers'!$C$4*'Inputs'!$F$24
B6: Customers lost per year before RM defence (gross churn) | C6: ='1. Customers'!$C$4*'Inputs'!$F$23
B7: …customers defended by RM retention activity | C7: ='1. Customers'!$C$5*'Inputs'!$F$23*'Inputs'!$F$168 | E7: RM-managed churn × defence effect (validate with holdouts)
B8: New customers onboarded per year (net churn replacement) | C8: ='1. Customers'!$C$6-'1. Customers'!$C$7 | E8: Drives onboarding workload and KYC costs
B10: PRODUCT VOLUMES & BALANCES
B11: Product | C11: Units (accounts / facilities) | D11: Avg balance per unit (£) | E11: Total balances (£) | F11: Note | G11: RM-held units | H11: Digitally-held units | I11: (segment granularity — scenario dimension)
B12: Business current accounts | C12: ='1. Customers'!$C$4*'Inputs'!$F$30 | D12: ='Inputs'!$F$31 | E12: =C12*D12 | F12: Credit balances held by customers | G12: =C12*'Inputs'!$F$148 | H12: =C12-G12
B13: Instant-access savings | C13: ='1. Customers'!$C$4*'1b. Demand & CEPs'!$J$41 | D13: ='Inputs'!$F$33 | E13: =C13*D13 | G13: =C13*'Inputs'!$F$149 | H13: =C13-G13
B14: Notice & fixed deposits | C14: ='1. Customers'!$C$4*'1b. Demand & CEPs'!$J$42 | D14: ='Inputs'!$F$35 | E14: =C14*D14 | G14: =C14*'Inputs'!$F$150 | H14: =C14-G14
B15: Business overdrafts | C15: ='1. Customers'!$C$4*'1b. Demand & CEPs'!$J$43 | D15: ='Inputs'!$F$37*'Inputs'!$F$38 | E15: =C15*D15 | F15: Balance = limit × utilisation (drawn) | G15: =C15*'Inputs'!$F$151 | H15: =C15-G15
B16: Term loans & comm. mortgages | C16: ='1. Customers'!$C$4*'1b. Demand & CEPs'!$J$44 | D16: ='Inputs'!$F$40 | E16: =C16*D16 | G16: =C16*'Inputs'!$F$152 | H16: =C16-G16
B17: Asset finance | C17: ='1. Customers'!$C$4*'1b. Demand & CEPs'!$J$45 | D17: ='Inputs'!$F$43 | E17: =C17*D17 | G17: =C17*'Inputs'!$F$153 | H17: =C17-G17
B18: Invoice finance | C18: ='1. Customers'!$C$4*'1b. Demand & CEPs'!$J$46 | D18: ='Inputs'!$F$46 | E18: =C18*D18 | F18: Funds in use (advances outstanding) | G18: =C18*'Inputs'!$F$154 | H18: =C18-G18
B19: Business credit cards | C19: ='1. Customers'!$C$4*'1b. Demand & CEPs'!$J$47 | D19: ='Inputs'!$F$52*'Inputs'!$F$51 | E19: =C19*D19 | F19: Avg interest-bearing balance per card | G19: =C19*'Inputs'!$F$155 | H19: =C19-G19
B20: Payments & FX (service users) | C20: ='1. Customers'!$C$4*'Inputs'!$F$53 | D20: =0 | E20: =C20*D20 | F20: No balance product | G20: =C20*'Inputs'!$F$156 | H20: =C20-G20
B21: Total customer deposits | E21: ='1. Customers'!$E$12+'1. Customers'!$E$13+'1. Customers'!$E$14
B22: Total lending balances | E22: ='1. Customers'!$E$15+'1. Customers'!$E$16+'1. Customers'!$E$17+'1. Customers'!$E$18+'1. Customers'!$E$19
D23: ='1. Customers'!$E$22/'1. Customers'!$E$21 | E23: Loan-to-deposit ratio:
B24: Total accounts on ledger (all products excl. FX users) | C24: ='1. Customers'!$C$12+'1. Customers'!$C$13+'1. Customers'!$C$14+'1. Customers'!$C$15+'1. Customers'!$C$16+'1. Customers'!$C$17+'1. Customers'!$C$18+'1. Customers'!$C$19 | E24: Driver for core banking system cost
B25: Total live credit facilities | C25: ='1. Customers'!$C$15+'1. Customers'!$C$16+'1. Customers'!$C$17+'1. Customers'!$C$18+'1. Customers'!$C$19 | E25: Driver for credit systems & monitoring cost

Sheet 1b. Demand & CEPs
B1: DEMAND LAYER — CATEGORY ENTRY POINTS
B2: One job to be done: 'I keep the business's money working.' A category entry point is a SITUATION in which that job arises — not a segment, not a product feature. At steady state a stock and a rate are the same statement (Little's Law), so this layer needs no time axis: penetration = (lambda*c x L) / (1 + lambda*c x L), where lambda*c = events x presence x conversion won per customer per year and L is the holding life. The saturating form is used because a customer holds at most one of each product at a time; it is bounded at 1, so no scenario can produce a penetration above 100%.
B3: SHIPPING POSTURE: the event, presence and conversion columns ship EMPTY on purpose. Each carries the cohort query that fills it. Assumed incidence rates get contradicted by a bank's own data inside one meeting, and that discredits the parts of the model that are right. Any product whose rows are unpopulated falls back to its hardcoded penetration, so the workbook is complete and inert until a bank fills it in.
B5: Mode (set on Inputs) | C5: ='Inputs'!$F$190
B7: FAMILY A — ACQUISITION CEPs (derive the customer count)
B8: ID | C8: Category entry point | D8: Events in catchment /yr | E8: Presence | F8: Conversion | G8: Won events /yr | H8: Tier | I8: Cost to be present (£/yr) | J8: Cohort query that fills this row
B9: A1 | C9: The business is formed or starts trading | G9: =IFERROR(D9*E9*F9,0) | H9: T2 | J9: [mental availability] Companies House incorporations in catchment postcodes /yr. Presence = prompted consideration at formation (brand tracker). Evidence held: >50% of start-ups default to the founder's personal-account bank (CMA 2016).
B10: A2 | C10: A service failure, fee shock or declined request breaks trust | G10: =IFERROR(D10*E10*F10,0) | H10: T2 | J10: [detection / rivals' availability] Complaints + fee-shock events + declines on own book /yr; for inbound, CASS switch-ins by stated reason. Evidence held: switching after formation runs 0.5-4%/yr.
B11: A3 | C11: A credit need arises the incumbent will not meet | G11: =IFERROR(D11*E11*F11,0) | H11: T4 | J11: [mental availability + broker] Broker-introduced applications /yr + declined-elsewhere flag on inbound applications.
B12: A4 | C12: Ownership or structure changes (incorporation, sale, merger) | G12: =IFERROR(D12*E12*F12,0) | H12: T4 | J12: [mental availability] Companies House filings for share transfers and re-registrations in catchment /yr.
B13: A5 | C13: An inducement is offered | G13: =IFERROR(D13*E13*F13,0) | H13: T2 | J13: [paid] Switch-offer redemptions /yr. Evidence held: BCR ISS moved 69,135 SMEs, GBP251.54m, >50% of all CASS SME switches in 28 months. Post-dowry retention was never published — loyalty purchase is unproven in both directions.
C14: Won acquisition events /yr | G14: =SUM(G9:G13) | I14: =SUM(I9:I13)
C15: Relationship life (= 1 / churn) | G15: =1/'Inputs'!$F$23
C16: Derived customers (won events x relationship life) | G16: ='1b. Demand & CEPs'!$G$14*'1b. Demand & CEPs'!$G$15
C17: Hardcoded customers (R x P) | G17: ='Inputs'!$F$21*'Inputs'!$F$22
C18: CALIBRATE — won events/yr implied by today's R x P | G18: ='1b. Demand & CEPs'!$G$17/'1b. Demand & CEPs'!$G$15 | J18: This is the number the five CEPs above must sum to. It equals the onboarding volume the model already computes on tab 1, so Little's Law closes on the acquisition side.
C19: MEMO — acquisition cost per won event | G19: =IFERROR('1b. Demand & CEPs'!$I$14/'1b. Demand & CEPs'!$G$14,0) | J19: Memo only in v1.3 — not posted to the P&L, so toggle OFF stays byte-identical. The current account, cards, savings and FX carry no acquisition cost anywhere in the model; this is the first place it is quantified.
C21: Customers in force | G21: =IF('1b. Demand & CEPs'!$C$5<>"LIVE",'1b. Demand & CEPs'!$G$17,IF('1b. Demand & CEPs'!$G$14=0,'1b. Demand & CEPs'!$G$17,'1b. Demand & CEPs'!$G$16))
B23: FAMILY B — CROSS-HOLDING CEPs (derive the eight product penetrations)
C24: The current account has no row here. It is the relationship itself, so it is derived by Family A and its penetration stays 100% by definition.
B25: ID | C25: Category entry point | D25: Events /cust/yr | E25: Presence | F25: Conversion | G25: Won /cust/yr | H25: Tier | I25: Product | J25: Cohort query that fills this row
B26: B1 | C26: A surplus balance sits idle past a threshold | G26: =IFERROR(D26*E26*F26,0) | H26: T1 | I26: sav | J26: [detection + default] Customer-months where the current-account balance exceeds a threshold for 90 days. Evidence held: GBP150bn of SME deposits sit inert; FCA auto-enrolment cut unpaid-item charges 21-24% where the self-registration arm achieved nothing. This is a default, not a campaign.
B27: B2 | C27: A known outgoing is dated 3-12 months ahead | G27: =IFERROR(D27*E27*F27,0) | H27: T4 | I27: dep | J27: [detection] Scheduled large debits (tax, planned capex) visible on the account 3-12 months out.
B28: B3 | C28: A balance approaches zero or a payment nearly fails | G28: =IFERROR(D28*E28*F28,0) | H28: T1 | I28: od | J28: [detection + alert] Near-miss events /customer/yr: balance below buffer, or a payment attempted against insufficient funds. Evidence held: FCA OP36/OP40 alerts cut unarranged charges ~25% — the only T1 evidence in UK banking.
B29: B4 | C29: A capital purchase or premises decision arises | G29: =IFERROR(D29*E29*F29,0) | H29: T4 | I29: loan | J29: [RM (already costed)] Loan applications by stated purpose = expansion or premises, per customer per year.
B30: B5 | C30: An existing facility reaches maturity | G30: =IFERROR(D30*E30*F30,0) | H30: T4 | I30: loan | J30: [RM (already costed)] Facilities reaching maturity /yr, from the book's own maturity ladder.
B31: B6 | C31: Equipment or a vehicle reaches end of life | G31: =IFERROR(D31*E31*F31,0) | H31: T4 | I31: af | J31: [RM (already costed)] Asset finance agreements reaching end of term, plus asset-register age where held.
B32: B7 | C32: A debtor goes past terms and opens a cash gap | G32: =IFERROR(D32*E32*F32,0) | H32: T4 | I32: inv | J32: [RM (already costed)] Customer-months where receivables ageing crosses terms — visible from transaction data on the current account.
B33: B8 | C33: An order arrives too large for working capital | G33: =IFERROR(D33*E33*F33,0) | H33: T4 | I33: inv | J33: [RM (already costed)] Single credits or invoices above a multiple of the customer's mean monthly turnover.
B34: B9 | C34: Recurring supplier spend needs separating from the account | G34: =IFERROR(D34*E34*F34,0) | H34: T2 | I34: card | J34: [default at onboarding] Customers with recurring card-type spend running through the current account. Evidence held: defaults beat persuasion — card-as-default-instrument at onboarding.
B35: B10 | C35: An employee needs delegated spend | G35: =IFERROR(D35*E35*F35,0) | H35: T4 | I35: card | J35: [detection] Payroll headcount growth events, or second-signatory requests.
B36: B11 | C36: A first overseas supplier invoice arrives | G36: =IFERROR(D36*E36*F36,0) | H36: T3 | I36: fx | J36: [detection] First outbound cross-border payment per customer. Evidence held: 80% of SMEs report confusion at bank FX fees — the thinnest evidence base in the set and the biggest testable prize.
B37: B12 | C37: A first overseas customer payment is received | G37: =IFERROR(D37*E37*F37,0) | H37: T3 | I37: fx | J37: [detection] First inbound cross-border receipt per customer.
B39: PRODUCT DERIVATION
B40: Code | C40: Product | D40: lambda*c (won /cust/yr) | E40: Holding life L | F40: Derived pen | G40: Hardcode pen | H40: CALIBRATE: implied lambda*c | I40: One won moment per (customer-yrs) | J40: PENETRATION IN FORCE
B41: sav | C41: Instant-access savings | D41: =SUMIF($I$26:$I$37,$B41,$G$26:$G$37) | E41: ='Inputs'!$F$191 | F41: =IFERROR(D41*E41/(1+D41*E41),0) | G41: ='Inputs'!$F$32 | H41: =IFERROR(G41/((1-G41)*E41),"") | I41: =IFERROR(1/H41,"") | J41: =IF('1b. Demand & CEPs'!$C$5<>"LIVE",G41,IF(OR(D41=0,E41=0),G41,F41))
B42: dep | C42: Notice & fixed deposits | D42: =SUMIF($I$26:$I$37,$B42,$G$26:$G$37) | E42: ='Inputs'!$F$192 | F42: =IFERROR(D42*E42/(1+D42*E42),0) | G42: ='Inputs'!$F$34 | H42: =IFERROR(G42/((1-G42)*E42),"") | I42: =IFERROR(1/H42,"") | J42: =IF('1b. Demand & CEPs'!$C$5<>"LIVE",G42,IF(OR(D42=0,E42=0),G42,F42))
B43: od | C43: Business overdrafts | D43: =SUMIF($I$26:$I$37,$B43,$G$26:$G$37) | E43: ='Inputs'!$F$193 | F43: =IFERROR(D43*E43/(1+D43*E43),0) | G43: ='Inputs'!$F$36 | H43: =IFERROR(G43/((1-G43)*E43),"") | I43: =IFERROR(1/H43,"") | J43: =IF('1b. Demand & CEPs'!$C$5<>"LIVE",G43,IF(OR(D43=0,E43=0),G43,F43))
B44: loan | C44: Term loans & comm. mortgages | D44: =SUMIF($I$26:$I$37,$B44,$G$26:$G$37) | E44: ='Inputs'!$F$41 | F44: =IFERROR(D44*E44/(1+D44*E44),0) | G44: ='Inputs'!$F$39 | H44: =IFERROR(G44/((1-G44)*E44),"") | I44: =IFERROR(1/H44,"") | J44: =IF('1b. Demand & CEPs'!$C$5<>"LIVE",G44,IF(OR(D44=0,E44=0),G44,F44))
B45: af | C45: Asset finance | D45: =SUMIF($I$26:$I$37,$B45,$G$26:$G$37) | E45: ='Inputs'!$F$44 | F45: =IFERROR(D45*E45/(1+D45*E45),0) | G45: ='Inputs'!$F$42 | H45: =IFERROR(G45/((1-G45)*E45),"") | I45: =IFERROR(1/H45,"") | J45: =IF('1b. Demand & CEPs'!$C$5<>"LIVE",G45,IF(OR(D45=0,E45=0),G45,F45))
...

Sheet 2. Revenues
B1: PRODUCT REVENUES — UNIT AND TOTAL
B2: Net interest margins measured against internal funds transfer prices (floating = Bank Rate; term = Bank Rate + premium).
B4: Product | C4: Units | D4: Avg balance /unit | E4: Customer rate | F4: FTP rate | G4: Margin % | H4: NII per unit | I4: Fees per unit | J4: Revenue per unit | K4: Total NII (£) | L4: Total fees (£) | M4: Total revenue (£)
B5: Business current accounts | C5: ='1. Customers'!$C$12 | D5: ='1. Customers'!$D$12 | E5: ='Inputs'!$F$58 | F5: ='Inputs'!$F$17 | G5: =F5-E5 | H5: =D5*G5 | I5: =12*'Inputs'!$F$59+'Inputs'!$F$60 | J5: =H5+I5 | K5: =H5*C5 | L5: =I5*C5 | M5: =J5*C5
B6: Instant-access savings | C6: ='1. Customers'!$C$13 | D6: ='1. Customers'!$D$13 | E6: ='Inputs'!$F$61 | F6: ='Inputs'!$F$17 | G6: =F6-E6 | H6: =D6*G6 | I6: =0 | J6: =H6+I6 | K6: =H6*C6 | L6: =I6*C6 | M6: =J6*C6
B7: Notice & fixed deposits | C7: ='1. Customers'!$C$14 | D7: ='1. Customers'!$D$14 | E7: ='Inputs'!$F$62 | F7: ='Inputs'!$F$18 | G7: =F7-E7 | H7: =D7*G7 | I7: =0 | J7: =H7+I7 | K7: =H7*C7 | L7: =I7*C7 | M7: =J7*C7
B8: Business overdrafts | C8: ='1. Customers'!$C$15 | D8: ='1. Customers'!$D$15 | E8: ='Inputs'!$F$63 | F8: ='Inputs'!$F$10 | G8: =E8-F8 | H8: =D8*G8 | I8: ='Inputs'!$F$64*'Inputs'!$F$37 | J8: =H8+I8 | K8: =H8*C8 | L8: =I8*C8 | M8: =J8*C8
B9: Term loans & comm. mortgages | C9: ='1. Customers'!$C$16 | D9: ='1. Customers'!$D$16 | E9: ='Inputs'!$F$65 | F9: ='Inputs'!$F$11 | G9: =E9-F9 | H9: =D9*G9 | I9: ='Inputs'!$F$66*'Inputs'!$F$40/'Inputs'!$F$41 | J9: =H9+I9 | K9: =H9*C9 | L9: =I9*C9 | M9: =J9*C9
B10: Asset finance | C10: ='1. Customers'!$C$17 | D10: ='1. Customers'!$D$17 | E10: ='Inputs'!$F$67 | F10: ='Inputs'!$F$11 | G10: =E10-F10 | H10: =D10*G10 | I10: =0 | J10: =H10+I10 | K10: =H10*C10 | L10: =I10*C10 | M10: =J10*C10
B11: Invoice finance | C11: ='1. Customers'!$C$18 | D11: ='1. Customers'!$D$18 | E11: ='Inputs'!$F$10+'Inputs'!$F$68 | F11: ='Inputs'!$F$10 | G11: =E11-F11 | H11: =D11*G11 | I11: ='Inputs'!$F$69*'Inputs'!$F$46*'Inputs'!$F$48 | J11: =H11+I11 | K11: =H11*C11 | L11: =I11*C11 | M11: =J11*C11
B12: Business credit cards | C12: ='1. Customers'!$C$19 | D12: ='1. Customers'!$D$19 | E12: ='Inputs'!$F$72 | F12: ='Inputs'!$F$10 | G12: =E12-F12 | H12: =D12*G12 | I12: ='Inputs'!$F$70*'Inputs'!$F$50*12+'Inputs'!$F$71 | J12: =H12+I12 | K12: =H12*C12 | L12: =I12*C12 | M12: =J12*C12
B13: Payments & FX | C13: ='1. Customers'!$C$20 | D13: ='1. Customers'!$D$20 | E13: =0 | F13: =0 | G13: =0 | H13: =D13*G13 | I13: ='Inputs'!$F$54*'Inputs'!$F$73+'Inputs'!$F$55*'Inputs'!$F$74 | J13: =H13+I13 | K13: =H13*C13 | L13: =I13*C13 | M13: =J13*C13
B14: TOTAL | K14: =SUM(K5:K13) | L14: =SUM(L5:L13) | M14: =SUM(M5:M13)
B16: Deposit products earn the spread between the transfer price and the rate paid; lending earns customer rate minus transfer price. Invoice finance service fees are charged on funded invoice value (≈8× funds in use).
B18: Memo — liquidity charge, already inside the deposit NII above (deposits × buffer × drag): | C18: =-'1. Customers'!$E$21*'Inputs'!$F$14*'Inputs'!$F$15
B19: Memo — behavioural deposit credit, already inside the deposit NII above (stable balances × credit): | C19: =('1. Customers'!$E$12+'1. Customers'!$E$13)*'Inputs'!$F$16

Sheet 3. HR & Activity
B1: STEP 2 — RUNNING COSTS: PEOPLE FROM ACTIVITY DRIVERS
B2: Every FTE is derived from transaction intensity (I) and customer load (L) — no headcount is assumed directly.
B4: Available hours per FTE per year | C4: ='Inputs'!$F$98*12 | E4: 147 hrs/month × 12
B5: Loaded hourly rate — relationship manager | C5: ='Inputs'!$F$99*(1+'Inputs'!$F$103)/'3. HR & Activity'!$C$4
B6: Loaded hourly rate — credit analyst | C6: ='Inputs'!$F$100*(1+'Inputs'!$F$103)/'3. HR & Activity'!$C$4
B7: Loaded hourly rate — service & operations | C7: ='Inputs'!$F$101*(1+'Inputs'!$F$103)/'3. HR & Activity'!$C$4
B9: ACTIVITY DRIVER TABLE (transaction intensity, I)
B10: Activity | C10: Product | D10: Role | E10: Driver volume /yr | F10: Hours per | G10: Total hours /yr | H10: Cost (£/yr) | I10: Flow (tab 9) | J10: Cost low (£/yr) | K10: Cost high (£/yr) | L10: Channel (scenario dimension) | M10: Process type | N10: Yield | O10: Attempts /yr | P10: Automation rate | Q10: BiC hours per | R10: BiC yield | S10: Benchmark source + tier | T10: £ gap to best in class
B11: Customer onboarding (KYC/AML, account setup) | C11: bca | D11: Service & ops | E11: ='1. Customers'!$C$8 | F11: ='Inputs'!$F$105 | G11: =O11*F11 | H11: =G11*'3. HR & Activity'!$C$7 | I11: CA-WP | J11: =H11*'Inputs'!$F$118 | K11: =H11*'Inputs'!$F$119 | L11: digital-amenable | M11: TRANSACTIONAL | N11: 1 | O11: =IF('Inputs'!$F$198<>"LIVE",E11,IF(M11<>"TRANSACTIONAL",E11,IF(OR(N11="",N11<=0),E11,E11/N11))) | T11: =IFERROR(IF(Q11="",0,O11*(F11-Q11)*'3. HR & Activity'!$C$7),0)+IFERROR(IF(OR(R11="",N11="",R11<=0,N11<=0),0,E11*(1/N11-1/R11)*F11*'3. HR & Activity'!$C$7),0)
B12: Current account servicing | C12: bca | D12: Service & ops | E12: ='1. Customers'!$C$12 | F12: ='Inputs'!$F$106 | G12: =O12*F12 | H12: =G12*'3. HR & Activity'!$C$7 | I12: CA-WP | J12: =H12*'Inputs'!$F$118 | K12: =H12*'Inputs'!$F$119 | L12: digital-amenable | M12: CONTINUOUS | O12: =IF('Inputs'!$F$198<>"LIVE",E12,IF(M12<>"TRANSACTIONAL",E12,IF(OR(N12="",N12<=0),E12,E12/N12))) | T12: =IFERROR(IF(Q12="",0,O12*(F12-Q12)*'3. HR & Activity'!$C$7),0)+IFERROR(IF(OR(R12="",N12="",R12<=0,N12<=0),0,E12*(1/N12-1/R12)*F12*'3. HR & Activity'!$C$7),0)
B13: Savings servicing | C13: sav | D13: Service & ops | E13: ='1. Customers'!$C$13 | F13: ='Inputs'!$F$107 | G13: =O13*F13 | H13: =G13*'3. HR & Activity'!$C$7 | I13: SV-WP | J13: =H13*'Inputs'!$F$118 | K13: =H13*'Inputs'!$F$119 | L13: digital-amenable | M13: CONTINUOUS | O13: =IF('Inputs'!$F$198<>"LIVE",E13,IF(M13<>"TRANSACTIONAL",E13,IF(OR(N13="",N13<=0),E13,E13/N13))) | T13: =IFERROR(IF(Q13="",0,O13*(F13-Q13)*'3. HR & Activity'!$C$7),0)+IFERROR(IF(OR(R13="",N13="",R13<=0,N13<=0),0,E13*(1/N13-1/R13)*F13*'3. HR & Activity'!$C$7),0)
B14: Deposit servicing | C14: dep | D14: Service & ops | E14: ='1. Customers'!$C$14 | F14: ='Inputs'!$F$108 | G14: =O14*F14 | H14: =G14*'3. HR & Activity'!$C$7 | I14: SV-WP | J14: =H14*'Inputs'!$F$118 | K14: =H14*'Inputs'!$F$119 | L14: digital-amenable | M14: CONTINUOUS | O14: =IF('Inputs'!$F$198<>"LIVE",E14,IF(M14<>"TRANSACTIONAL",E14,IF(OR(N14="",N14<=0),E14,E14/N14))) | T14: =IFERROR(IF(Q14="",0,O14*(F14-Q14)*'3. HR & Activity'!$C$7),0)+IFERROR(IF(OR(R14="",N14="",R14<=0,N14<=0),0,E14*(1/N14-1/R14)*F14*'3. HR & Activity'!$C$7),0)
B15: Overdraft reviews & renewals | C15: od | D15: Credit analyst | E15: ='1. Customers'!$C$15 | F15: ='Inputs'!$F$109 | G15: =O15*F15 | H15: =G15*'3. HR & Activity'!$C$6 | I15: LN-WP | J15: =H15*'Inputs'!$F$118 | K15: =H15*'Inputs'!$F$119 | L15: judgement | M15: CONTINUOUS | O15: =IF('Inputs'!$F$198<>"LIVE",E15,IF(M15<>"TRANSACTIONAL",E15,IF(OR(N15="",N15<=0),E15,E15/N15))) | T15: =IFERROR(IF(Q15="",0,O15*(F15-Q15)*'3. HR & Activity'!$C$6),0)+IFERROR(IF(OR(R15="",N15="",R15<=0,N15<=0),0,E15*(1/N15-1/R15)*F15*'3. HR & Activity'!$C$6),0)
B16: Term loan underwriting (new loans) | C16: loan | D16: Credit analyst | E16: ='1. Customers'!$C$16/'Inputs'!$F$41 | F16: ='Inputs'!$F$110 | G16: =O16*F16 | H16: =G16*'3. HR & Activity'!$C$6 | I16: LN-WP | J16: =H16*'Inputs'!$F$118 | K16: =H16*'Inputs'!$F$119 | L16: judgement | M16: TRANSACTIONAL | N16: 1 | O16: =IF('Inputs'!$F$198<>"LIVE",E16,IF(M16<>"TRANSACTIONAL",E16,IF(OR(N16="",N16<=0),E16,E16/N16))) | T16: =IFERROR(IF(Q16="",0,O16*(F16-Q16)*'3. HR & Activity'!$C$6),0)+IFERROR(IF(OR(R16="",N16="",R16<=0,N16<=0),0,E16*(1/N16-1/R16)*F16*'3. HR & Activity'!$C$6),0)
B17: Term loan annual reviews | C17: loan | D17: Credit analyst | E17: ='1. Customers'!$C$16 | F17: ='Inputs'!$F$111 | G17: =O17*F17 | H17: =G17*'3. HR & Activity'!$C$6 | I17: LN-WP | J17: =H17*'Inputs'!$F$118 | K17: =H17*'Inputs'!$F$119 | L17: judgement | M17: CONTINUOUS | O17: =IF('Inputs'!$F$198<>"LIVE",E17,IF(M17<>"TRANSACTIONAL",E17,IF(OR(N17="",N17<=0),E17,E17/N17))) | T17: =IFERROR(IF(Q17="",0,O17*(F17-Q17)*'3. HR & Activity'!$C$6),0)+IFERROR(IF(OR(R17="",N17="",R17<=0,N17<=0),0,E17*(1/N17-1/R17)*F17*'3. HR & Activity'!$C$6),0)
B18: Asset finance origination | C18: af | D18: Credit analyst | E18: ='1. Customers'!$C$17/'Inputs'!$F$44 | F18: ='Inputs'!$F$112 | G18: =O18*F18 | H18: =G18*'3. HR & Activity'!$C$6 | I18: LN-WP | J18: =H18*'Inputs'!$F$118 | K18: =H18*'Inputs'!$F$119 | L18: digital-amenable | M18: TRANSACTIONAL | N18: 1 | O18: =IF('Inputs'!$F$198<>"LIVE",E18,IF(M18<>"TRANSACTIONAL",E18,IF(OR(N18="",N18<=0),E18,E18/N18))) | T18: =IFERROR(IF(Q18="",0,O18*(F18-Q18)*'3. HR & Activity'!$C$6),0)+IFERROR(IF(OR(R18="",N18="",R18<=0,N18<=0),0,E18*(1/N18-1/R18)*F18*'3. HR & Activity'!$C$6),0)
B19: Invoice finance client onboarding | C19: inv | D19: Credit analyst | E19: ='1. Customers'!$C$18/'Inputs'!$F$47 | F19: ='Inputs'!$F$113 | G19: =O19*F19 | H19: =G19*'3. HR & Activity'!$C$6 | I19: LN-WP | J19: =H19*'Inputs'!$F$118 | K19: =H19*'Inputs'!$F$119 | L19: judgement | M19: TRANSACTIONAL | N19: 1 | O19: =IF('Inputs'!$F$198<>"LIVE",E19,IF(M19<>"TRANSACTIONAL",E19,IF(OR(N19="",N19<=0),E19,E19/N19))) | T19: =IFERROR(IF(Q19="",0,O19*(F19-Q19)*'3. HR & Activity'!$C$6),0)+IFERROR(IF(OR(R19="",N19="",R19<=0,N19<=0),0,E19*(1/N19-1/R19)*F19*'3. HR & Activity'!$C$6),0)
B20: Invoice finance monitoring | C20: inv | D20: Credit analyst | E20: ='1. Customers'!$C$18 | F20: ='Inputs'!$F$114*12 | G20: =O20*F20 | H20: =G20*'3. HR & Activity'!$C$6 | I20: LN-WP | J20: =H20*'Inputs'!$F$118 | K20: =H20*'Inputs'!$F$119 | L20: judgement | M20: CONTINUOUS | O20: =IF('Inputs'!$F$198<>"LIVE",E20,IF(M20<>"TRANSACTIONAL",E20,IF(OR(N20="",N20<=0),E20,E20/N20))) | T20: =IFERROR(IF(Q20="",0,O20*(F20-Q20)*'3. HR & Activity'!$C$6),0)+IFERROR(IF(OR(R20="",N20="",R20<=0,N20<=0),0,E20*(1/N20-1/R20)*F20*'3. HR & Activity'!$C$6),0)
B21: Card servicing | C21: card | D21: Service & ops | E21: ='1. Customers'!$C$19 | F21: ='Inputs'!$F$115 | G21: =O21*F21 | H21: =G21*'3. HR & Activity'!$C$7 | I21: CC-WP | J21: =H21*'Inputs'!$F$118 | K21: =H21*'Inputs'!$F$119 | L21: digital-amenable | M21: CONTINUOUS | O21: =IF('Inputs'!$F$198<>"LIVE",E21,IF(M21<>"TRANSACTIONAL",E21,IF(OR(N21="",N21<=0),E21,E21/N21))) | T21: =IFERROR(IF(Q21="",0,O21*(F21-Q21)*'3. HR & Activity'!$C$7),0)+IFERROR(IF(OR(R21="",N21="",R21<=0,N21<=0),0,E21*(1/N21-1/R21)*F21*'3. HR & Activity'!$C$7),0)
B22: Payments & FX support | C22: fx | D22: Service & ops | E22: ='1. Customers'!$C$20 | F22: ='Inputs'!$F$116 | G22: =O22*F22 | H22: =G22*'3. HR & Activity'!$C$7 | I22: PX-WP | J22: =H22*'Inputs'!$F$118 | K22: =H22*'Inputs'!$F$119 | L22: digital-amenable | M22: CONTINUOUS | O22: =IF('Inputs'!$F$198<>"LIVE",E22,IF(M22<>"TRANSACTIONAL",E22,IF(OR(N22="",N22<=0),E22,E22/N22))) | T22: =IFERROR(IF(Q22="",0,O22*(F22-Q22)*'3. HR & Activity'!$C$7),0)+IFERROR(IF(OR(R22="",N22="",R22<=0,N22<=0),0,E22*(1/N22-1/R22)*F22*'3. HR & Activity'!$C$7),0)
B23: Collections — overdrafts | C23: od | D23: Credit analyst | E23: ='1. Customers'!$C$15*'Inputs'!$F$117 | F23: ='Inputs'!$F$120 | G23: =O23*F23 | H23: =G23*'3. HR & Activity'!$C$6 | I23: LN-WP | J23: =H23*'Inputs'!$F$118 | K23: =H23*'Inputs'!$F$119 | L23: judgement | M23: CONTINUOUS | O23: =IF('Inputs'!$F$198<>"LIVE",E23,IF(M23<>"TRANSACTIONAL",E23,IF(OR(N23="",N23<=0),E23,E23/N23))) | T23: =IFERROR(IF(Q23="",0,O23*(F23-Q23)*'3. HR & Activity'!$C$6),0)+IFERROR(IF(OR(R23="",N23="",R23<=0,N23<=0),0,E23*(1/N23-1/R23)*F23*'3. HR & Activity'!$C$6),0)
B24: Collections — term loans | C24: loan | D24: Credit analyst | E24: ='1. Customers'!$C$16*'Inputs'!$F$117 | F24: ='Inputs'!$F$120 | G24: =O24*F24 | H24: =G24*'3. HR & Activity'!$C$6 | I24: LN-WP | J24: =H24*'Inputs'!$F$118 | K24: =H24*'Inputs'!$F$119 | L24: judgement | M24: CONTINUOUS | O24: =IF('Inputs'!$F$198<>"LIVE",E24,IF(M24<>"TRANSACTIONAL",E24,IF(OR(N24="",N24<=0),E24,E24/N24))) | T24: =IFERROR(IF(Q24="",0,O24*(F24-Q24)*'3. HR & Activity'!$C$6),0)+IFERROR(IF(OR(R24="",N24="",R24<=0,N24<=0),0,E24*(1/N24-1/R24)*F24*'3. HR & Activity'!$C$6),0)
B25: Collections — asset finance | C25: af | D25: Credit analyst | E25: ='1. Customers'!$C$17*'Inputs'!$F$117 | F25: ='Inputs'!$F$120 | G25: =O25*F25 | H25: =G25*'3. HR & Activity'!$C$6 | I25: LN-WP | J25: =H25*'Inputs'!$F$118 | K25: =H25*'Inputs'!$F$119 | L25: judgement | M25: CONTINUOUS | O25: =IF('Inputs'!$F$198<>"LIVE",E25,IF(M25<>"TRANSACTIONAL",E25,IF(OR(N25="",N25<=0),E25,E25/N25))) | T25: =IFERROR(IF(Q25="",0,O25*(F25-Q25)*'3. HR & Activity'!$C$6),0)+IFERROR(IF(OR(R25="",N25="",R25<=0,N25<=0),0,E25*(1/N25-1/R25)*F25*'3. HR & Activity'!$C$6),0)
B26: Collections — invoice finance | C26: inv | D26: Credit analyst | E26: ='1. Customers'!$C$18*'Inputs'!$F$117 | F26: ='Inputs'!$F$120 | G26: =O26*F26 | H26: =G26*'3. HR & Activity'!$C$6 | I26: LN-WP | J26: =H26*'Inputs'!$F$118 | K26: =H26*'Inputs'!$F$119 | L26: judgement | M26: CONTINUOUS | O26: =IF('Inputs'!$F$198<>"LIVE",E26,IF(M26<>"TRANSACTIONAL",E26,IF(OR(N26="",N26<=0),E26,E26/N26))) | T26: =IFERROR(IF(Q26="",0,O26*(F26-Q26)*'3. HR & Activity'!$C$6),0)+IFERROR(IF(OR(R26="",N26="",R26<=0,N26<=0),0,E26*(1/N26-1/R26)*F26*'3. HR & Activity'!$C$6),0)
B27: Collections — cards | C27: card | D27: Credit analyst | E27: ='1. Customers'!$C$19*'Inputs'!$F$117 | F27: ='Inputs'!$F$120 | G27: =O27*F27 | H27: =G27*'3. HR & Activity'!$C$6 | I27: CC-WP | J27: =H27*'Inputs'!$F$118 | K27: =H27*'Inputs'!$F$119 | L27: judgement | M27: CONTINUOUS | O27: =IF('Inputs'!$F$198<>"LIVE",E27,IF(M27<>"TRANSACTIONAL",E27,IF(OR(N27="",N27<=0),E27,E27/N27))) | T27: =IFERROR(IF(Q27="",0,O27*(F27-Q27)*'3. HR & Activity'!$C$6),0)+IFERROR(IF(OR(R27="",N27="",R27<=0,N27<=0),0,E27*(1/N27-1/R27)*F27*'3. HR & Activity'!$C$6),0)
B28: Collateral administration — term loans | C28: loan | D28: Credit analyst | E28: ='1. Customers'!$C$16 | F28: ='Inputs'!$F$121 | G28: =O28*F28 | H28: =G28*'3. HR & Activity'!$C$6 | I28: LN-WP | J28: =H28*'Inputs'!$F$118 | K28: =H28*'Inputs'!$F$119 | L28: digital-amenable | M28: CONTINUOUS | O28: =IF('Inputs'!$F$198<>"LIVE",E28,IF(M28<>"TRANSACTIONAL",E28,IF(OR(N28="",N28<=0),E28,E28/N28))) | T28: =IFERROR(IF(Q28="",0,O28*(F28-Q28)*'3. HR & Activity'!$C$6),0)+IFERROR(IF(OR(R28="",N28="",R28<=0,N28<=0),0,E28*(1/N28-1/R28)*F28*'3. HR & Activity'!$C$6),0)
B29: Collateral administration — asset finance | C29: af | D29: Credit analyst | E29: ='1. Customers'!$C$17 | F29: ='Inputs'!$F$121 | G29: =O29*F29 | H29: =G29*'3. HR & Activity'!$C$6 | I29: LN-WP | J29: =H29*'Inputs'!$F$118 | K29: =H29*'Inputs'!$F$119 | L29: digital-amenable | M29: CONTINUOUS | O29: =IF('Inputs'!$F$198<>"LIVE",E29,IF(M29<>"TRANSACTIONAL",E29,IF(OR(N29="",N29<=0),E29,E29/N29))) | T29: =IFERROR(IF(Q29="",0,O29*(F29-Q29)*'3. HR & Activity'!$C$6),0)+IFERROR(IF(OR(R29="",N29="",R29<=0,N29<=0),0,E29*(1/N29-1/R29)*F29*'3. HR & Activity'!$C$6),0)
B30: Collateral administration — invoice finance | C30: inv | D30: Credit analyst | E30: ='1. Customers'!$C$18 | F30: ='Inputs'!$F$121 | G30: =O30*F30 | H30: =G30*'3. HR & Activity'!$C$6 | I30: LN-WP | J30: =H30*'Inputs'!$F$118 | K30: =H30*'Inputs'!$F$119 | L30: digital-amenable | M30: CONTINUOUS | O30: =IF('Inputs'!$F$198<>"LIVE",E30,IF(M30<>"TRANSACTIONAL",E30,IF(OR(N30="",N30<=0),E30,E30/N30))) | T30: =IFERROR(IF(Q30="",0,O30*(F30-Q30)*'3. HR & Activity'!$C$6),0)+IFERROR(IF(OR(R30="",N30="",R30<=0,N30<=0),0,E30*(1/N30-1/R30)*F30*'3. HR & Activity'!$C$6),0)
B31: Recoveries & workout — term loans | C31: loan | D31: Credit analyst | E31: ='1. Customers'!$C$16*'Inputs'!$F$117 | F31: ='Inputs'!$F$122 | G31: =O31*F31 | H31: =G31*'3. HR & Activity'!$C$6 | I31: LN-WP | J31: =H31*'Inputs'!$F$118 | K31: =H31*'Inputs'!$F$119 | L31: judgement | M31: CONTINUOUS | O31: =IF('Inputs'!$F$198<>"LIVE",E31,IF(M31<>"TRANSACTIONAL",E31,IF(OR(N31="",N31<=0),E31,E31/N31))) | T31: =IFERROR(IF(Q31="",0,O31*(F31-Q31)*'3. HR & Activity'!$C$6),0)+IFERROR(IF(OR(R31="",N31="",R31<=0,N31<=0),0,E31*(1/N31-1/R31)*F31*'3. HR & Activity'!$C$6),0)
B32: Recoveries & workout — asset finance | C32: af | D32: Credit analyst | E32: ='1. Customers'!$C$17*'Inputs'!$F$117 | F32: ='Inputs'!$F$122 | G32: =O32*F32 | H32: =G32*'3. HR & Activity'!$C$6 | I32: LN-WP | J32: =H32*'Inputs'!$F$118 | K32: =H32*'Inputs'!$F$119 | L32: judgement | M32: CONTINUOUS | O32: =IF('Inputs'!$F$198<>"LIVE",E32,IF(M32<>"TRANSACTIONAL",E32,IF(OR(N32="",N32<=0),E32,E32/N32))) | T32: =IFERROR(IF(Q32="",0,O32*(F32-Q32)*'3. HR & Activity'!$C$6),0)+IFERROR(IF(OR(R32="",N32="",R32<=0,N32<=0),0,E32*(1/N32-1/R32)*F32*'3. HR & Activity'!$C$6),0)
B33: Recoveries & workout — invoice finance | C33: inv | D33: Credit analyst | E33: ='1. Customers'!$C$18*'Inputs'!$F$117 | F33: ='Inputs'!$F$122 | G33: =O33*F33 | H33: =G33*'3. HR & Activity'!$C$6 | I33: LN-WP | J33: =H33*'Inputs'!$F$118 | K33: =H33*'Inputs'!$F$119 | L33: judgement | M33: CONTINUOUS | O33: =IF('Inputs'!$F$198<>"LIVE",E33,IF(M33<>"TRANSACTIONAL",E33,IF(OR(N33="",N33<=0),E33,E33/N33))) | T33: =IFERROR(IF(Q33="",0,O33*(F33-Q33)*'3. HR & Activity'!$C$6),0)+IFERROR(IF(OR(R33="",N33="",R33<=0,N33<=0),0,E33*(1/N33-1/R33)*F33*'3. HR & Activity'!$C$6),0)
B35: FTE REQUIREMENT & COST (customer load, L)
B36: Role | D36: FTEs | E36: Salary (£) | H36: Total cost (£/yr)
B37: Relationship managers (portfolio-driven) | D37: ='1. Customers'!$C$5/'Inputs'!$F$25 | E37: ='Inputs'!$F$99 | H37: =D37*E37*(1+'Inputs'!$F$103)
B38: Credit analysts / underwriters (activity-driven) | D38: =SUMIF('3. HR & Activity'!$D$11:$D$33,"Credit analyst",'3. HR & Activity'!$G$11:$G$33)/'3. HR & Activity'!$C$4 | E38: ='Inputs'!$F$100 | H38: =D38*E38*(1+'Inputs'!$F$103)
B39: Service & operations (activity-driven) | D39: =SUMIF('3. HR & Activity'!$D$11:$D$33,"Service & ops",'3. HR & Activity'!$G$11:$G$33)/'3. HR & Activity'!$C$4 | E39: ='Inputs'!$F$101 | H39: =D39*E39*(1+'Inputs'!$F$103)
B40: Team managers (span-driven) | D40: =('3. HR & Activity'!$D$37+'3. HR & Activity'!$D$38+'3. HR & Activity'!$D$39)/'Inputs'!$F$104 | E40: ='Inputs'!$F$102 | H40: =D40*E40*(1+'Inputs'!$F$103)
B41: TOTAL OPERATING-UNIT STAFF | D41: ='3. HR & Activity'!$D$37+'3. HR & Activity'!$D$38+'3. HR & Activity'!$D$39+'3. HR & Activity'!$D$40 | H41: ='3. HR & Activity'!$H$37+'3. HR & Activity'!$H$38+'3. HR & Activity'!$H$39+'3. HR & Activity'!$H$40
B43: Loaded hourly rates spread salary + on-costs over available hours; activity costs therefore reconcile exactly to analyst and service payroll.
B45: THE RM SYSTEM — ORIGINATE / STEWARD / DEFEND (three activities, one system)
...

Sheet 3b. Process Index
B1: PROCESS INDEX — WHICH PROCESS MOVES WHICH NUMBER
B2: Derived view. No assumptions live here. Every process in the model, with the flow it belongs to, the number it moves, its cost, and its gap to best in class. Filter the 'moves' column to answer 'what do I improve to change this number?'. Grouping is by the flow and product tags the model already carries, not by hand-maintained cell references — tags are load-bearing, cell references rot.
B4: Process | C4: Block | D4: Product | E4: Flow | F4: Accountable owner | G4: Moves these numbers | H4: Cost (£/yr) | I4: £ gap to BiC
B5: Customer onboarding (KYC/AML, account setup) | C5: operating unit | D5: bca | E5: CA-WP | F5: ='3. HR & Activity'!$D$11 | G5: BCA volumes · payments income · fraud cost | H5: ='3. HR & Activity'!$H$11 | I5: ='3. HR & Activity'!$T$11
B6: Current account servicing | C6: operating unit | D6: bca | E6: CA-WP | F6: ='3. HR & Activity'!$D$12 | G6: BCA volumes · payments income · fraud cost | H6: ='3. HR & Activity'!$H$12 | I6: ='3. HR & Activity'!$T$12
B7: Savings servicing | C7: operating unit | D7: sav | E7: SV-WP | F7: ='3. HR & Activity'!$D$13 | G7: Savings balances · deposit NII | H7: ='3. HR & Activity'!$H$13 | I7: ='3. HR & Activity'!$T$13
B8: Deposit servicing | C8: operating unit | D8: dep | E8: SV-WP | F8: ='3. HR & Activity'!$D$14 | G8: Term deposit balances · deposit NII | H8: ='3. HR & Activity'!$H$14 | I8: ='3. HR & Activity'!$T$14
B9: Overdraft reviews & renewals | C9: operating unit | D9: od | E9: LN-WP | F9: ='3. HR & Activity'!$D$15 | G9: Overdraft balances · overdraft income · cost of risk | H9: ='3. HR & Activity'!$H$15 | I9: ='3. HR & Activity'!$T$15
B10: Term loan underwriting (new loans) | C10: operating unit | D10: loan | E10: LN-WP | F10: ='3. HR & Activity'!$D$16 | G10: Loan balances · loan NII · cost of risk · RWA | H10: ='3. HR & Activity'!$H$16 | I10: ='3. HR & Activity'!$T$16
B11: Term loan annual reviews | C11: operating unit | D11: loan | E11: LN-WP | F11: ='3. HR & Activity'!$D$17 | G11: Loan balances · loan NII · cost of risk · RWA | H11: ='3. HR & Activity'!$H$17 | I11: ='3. HR & Activity'!$T$17
B12: Asset finance origination | C12: operating unit | D12: af | E12: LN-WP | F12: ='3. HR & Activity'!$D$18 | G12: Asset finance balances · AF yield · RWA | H12: ='3. HR & Activity'!$H$18 | I12: ='3. HR & Activity'!$T$18
B13: Invoice finance client onboarding | C13: operating unit | D13: inv | E13: LN-WP | F13: ='3. HR & Activity'!$D$19 | G13: Invoice finance funds in use · discount + service fees | H13: ='3. HR & Activity'!$H$19 | I13: ='3. HR & Activity'!$T$19
B14: Invoice finance monitoring | C14: operating unit | D14: inv | E14: LN-WP | F14: ='3. HR & Activity'!$D$20 | G14: Invoice finance funds in use · discount + service fees | H14: ='3. HR & Activity'!$H$20 | I14: ='3. HR & Activity'!$T$20
B15: Card servicing | C15: operating unit | D15: card | E15: CC-WP | F15: ='3. HR & Activity'!$D$21 | G15: Card balances · interchange · card fees | H15: ='3. HR & Activity'!$H$21 | I15: ='3. HR & Activity'!$T$21
B16: Payments & FX support | C16: operating unit | D16: fx | E16: PX-WP | F16: ='3. HR & Activity'!$D$22 | G16: FX volume · FX margin · payment fees | H16: ='3. HR & Activity'!$H$22 | I16: ='3. HR & Activity'!$T$22
B17: Collections — overdrafts | C17: operating unit | D17: od | E17: LN-WP | F17: ='3. HR & Activity'!$D$23 | G17: Overdraft balances · overdraft income · cost of risk | H17: ='3. HR & Activity'!$H$23 | I17: ='3. HR & Activity'!$T$23
B18: Collections — term loans | C18: operating unit | D18: loan | E18: LN-WP | F18: ='3. HR & Activity'!$D$24 | G18: Loan balances · loan NII · cost of risk · RWA | H18: ='3. HR & Activity'!$H$24 | I18: ='3. HR & Activity'!$T$24
B19: Collections — asset finance | C19: operating unit | D19: af | E19: LN-WP | F19: ='3. HR & Activity'!$D$25 | G19: Asset finance balances · AF yield · RWA | H19: ='3. HR & Activity'!$H$25 | I19: ='3. HR & Activity'!$T$25
B20: Collections — invoice finance | C20: operating unit | D20: inv | E20: LN-WP | F20: ='3. HR & Activity'!$D$26 | G20: Invoice finance funds in use · discount + service fees | H20: ='3. HR & Activity'!$H$26 | I20: ='3. HR & Activity'!$T$26
B21: Collections — cards | C21: operating unit | D21: card | E21: CC-WP | F21: ='3. HR & Activity'!$D$27 | G21: Card balances · interchange · card fees | H21: ='3. HR & Activity'!$H$27 | I21: ='3. HR & Activity'!$T$27
B22: Collateral administration — term loans | C22: operating unit | D22: loan | E22: LN-WP | F22: ='3. HR & Activity'!$D$28 | G22: Loan balances · loan NII · cost of risk · RWA | H22: ='3. HR & Activity'!$H$28 | I22: ='3. HR & Activity'!$T$28
B23: Collateral administration — asset finance | C23: operating unit | D23: af | E23: LN-WP | F23: ='3. HR & Activity'!$D$29 | G23: Asset finance balances · AF yield · RWA | H23: ='3. HR & Activity'!$H$29 | I23: ='3. HR & Activity'!$T$29
B24: Collateral administration — invoice finance | C24: operating unit | D24: inv | E24: LN-WP | F24: ='3. HR & Activity'!$D$30 | G24: Invoice finance funds in use · discount + service fees | H24: ='3. HR & Activity'!$H$30 | I24: ='3. HR & Activity'!$T$30
B25: Recoveries & workout — term loans | C25: operating unit | D25: loan | E25: LN-WP | F25: ='3. HR & Activity'!$D$31 | G25: Loan balances · loan NII · cost of risk · RWA | H25: ='3. HR & Activity'!$H$31 | I25: ='3. HR & Activity'!$T$31
B26: Recoveries & workout — asset finance | C26: operating unit | D26: af | E26: LN-WP | F26: ='3. HR & Activity'!$D$32 | G26: Asset finance balances · AF yield · RWA | H26: ='3. HR & Activity'!$H$32 | I26: ='3. HR & Activity'!$T$32
B27: Recoveries & workout — invoice finance | C27: operating unit | D27: inv | E27: LN-WP | F27: ='3. HR & Activity'!$D$33 | G27: Invoice finance funds in use · discount + service fees | H27: ='3. HR & Activity'!$H$33 | I27: ='3. HR & Activity'!$T$33
B28: KYC & financial crime (new-customer onboarding) | C28: head office | D28: risk | E28: CA-WP | F28: Financial crime ops | G28: Cost:income · operating cost per customer | H28: ='3. HR & Activity'!$H$75 | I28: ='3. HR & Activity'!$T$75
B29: KYC refresh & ongoing screening | C29: head office | D29: risk | E29: S1 | F29: Financial crime ops | G29: Cost:income · operating cost per customer | H29: ='3. HR & Activity'!$H$76 | I29: ='3. HR & Activity'!$T$76
B30: Payments operations & processing | C30: head office | D30: tech | E30: CA-PP1 | F30: Payments ops | G30: Cost:income · operating cost per customer | H30: ='3. HR & Activity'!$H$77 | I30: ='3. HR & Activity'!$T$77
B31: Core banking system | C31: head office | D31: tech | E31: E1 | F31: Technology | G31: Cost:income · operating cost per customer | H31: ='3. HR & Activity'!$H$78 | I31: ='3. HR & Activity'!$T$78
B32: Credit systems & portfolio monitoring | C32: head office | D32: tech | E32: LN-WP | F32: Credit risk | G32: Cost:income · operating cost per customer | H32: ='3. HR & Activity'!$H$79 | I32: ='3. HR & Activity'!$T$79
B33: Party reference data | C33: head office | D33: tech | E33: I1 | F33: Data management | G33: Cost:income · operating cost per customer | H33: ='3. HR & Activity'!$H$80 | I33: ='3. HR & Activity'!$T$80
B34: Product directory & pricing | C34: head office | D34: corp | E34: I2 | F34: Product management | G34: Cost:income · operating cost per customer · acquisition | H34: ='3. HR & Activity'!$H$81 | I34: ='3. HR & Activity'!$T$81
B35: Regulatory compliance & reporting | C35: head office | D35: risk | E35: S2 | F35: Compliance | G35: Cost:income · operating cost per customer | H35: ='3. HR & Activity'!$H$82 | I35: ='3. HR & Activity'!$T$82
B36: Sanctions screening / CDD | C36: head office | D36: risk | E36: S1 | F36: Financial crime ops | G36: Cost:income · operating cost per customer | H36: ='3. HR & Activity'!$H$83 | I36: ='3. HR & Activity'!$T$83
B37: Card scheme & merchant relations | C37: head office | D37: tech | E37: CC-PP1 | F37: Cards | G37: Cost:income · operating cost per customer | H37: ='3. HR & Activity'!$H$84 | I37: ='3. HR & Activity'!$T$84
B38: Operational risk | C38: head office | D38: risk | E38: S4 | F38: Operational risk | G38: Cost:income · operating cost per customer | H38: ='3. HR & Activity'!$H$85 | I38: ='3. HR & Activity'!$T$85
B39: Customer access entitlement / authentication | C39: head office | D39: tech | E39: E4 | F39: Technology | G39: Cost:income · operating cost per customer | H39: ='3. HR & Activity'!$H$86 | I39: ='3. HR & Activity'!$T$86
B40: Financial message gateway (Open Banking / API) | C40: head office | D40: tech | E40: E2 | F40: Technology | G40: Cost:income · operating cost per customer | H40: ='3. HR & Activity'!$H$87 | I40: ='3. HR & Activity'!$T$87
B41: Document & contract management | C41: head office | D41: tech | E41: E3 | F41: Technology | G41: Cost:income · operating cost per customer | H41: ='3. HR & Activity'!$H$88 | I41: ='3. HR & Activity'!$T$88
...

Sheet 4. Running Costs
B1: STEP 2 (CONT.) — TOTAL RUNNING COSTS OF THE OPERATING UNIT
B3: Unit HR cost (from HR & Activity sheet) | C3: ='3. HR & Activity'!$H$41
B4: Premises & facilities | C4: ='3. HR & Activity'!$D$41*'Inputs'!$F$125 | D4: CP1 · all WP | E4: FTEs × cost per FTE
B5: Equipment & fit-out depreciation | C5: ='3. HR & Activity'!$D$41*'Inputs'!$F$126 | D5: E1
B6: Other direct running costs | C6: ='4. Running Costs'!$C$3*'Inputs'!$F$127 | D6: E1 | E6: Travel, training, sundry — % of HR
B7: Unit-level platform & processing | C7: ='Inputs'!$F$182*'Inputs'!$F$128*('1. Customers'!$C$4/'Inputs'!$F$182)^'Inputs'!$F$181 | D7: S2 | E7: Per-customer core banking & payments processing
B8: Fraud & payment losses (incl. APP reimbursement) | C8: ='Inputs'!$F$142*'1. Customers'!$C$12 | D8: E1 | E8: Driver: current accounts — the payment-carrying product
B9: FSCS deposit-protection levy | C9: =('1. Customers'!$E$12+'1. Customers'!$E$13+'1. Customers'!$E$14)*'Inputs'!$F$144*'Inputs'!$F$143 | D9: CA-WP | E9: Driver: FSCS-protected deposit balances
B10: TOTAL DIRECT RUNNING COSTS | C10: ='4. Running Costs'!$C$3+'4. Running Costs'!$C$4+'4. Running Costs'!$C$5+'4. Running Costs'!$C$6+'4. Running Costs'!$C$7+'4. Running Costs'!$C$8+'4. Running Costs'!$C$9 | D10: SV-WP
B12: SHARE OF HEAD-OFFICE RUNNING COSTS
B13: Technology & central operations | C13: ='Inputs'!$F$182*'Inputs'!$F$129*('1. Customers'!$C$4/'Inputs'!$F$182)^'Inputs'!$F$181+'Inputs'!$F$185 | E13: Per-customer rate + fixed component (Inputs section N)
B14: Risk, compliance, financial crime & audit | C14: ='Inputs'!$F$182*'Inputs'!$F$130*('1. Customers'!$C$4/'Inputs'!$F$182)^'Inputs'!$F$181+'Inputs'!$F$186 | E14: Per-customer rate + fixed component (Inputs section N)
B15: Finance, HR, exec, brand & residual marketing | C15: ='Inputs'!$F$182*'Inputs'!$F$131*('1. Customers'!$C$4/'Inputs'!$F$182)^'Inputs'!$F$181+'Inputs'!$F$187 | E15: Per-customer rate + fixed component (Inputs section N)
B16: Churn replacement — acquisition marketing (driver: new customers won) | C16: ='1. Customers'!$C$8*'Inputs'!$F$136 | E16: Demand generation to replace churned customers; scales with the churn input
B17: TOTAL HEAD-OFFICE ALLOCATION | C17: ='4. Running Costs'!$C$13+'4. Running Costs'!$C$14+'4. Running Costs'!$C$15+'4. Running Costs'!$C$16
B19: Change-the-bank / transformation (portfolio hurdle — no product driver) | C19: ='Inputs'!$F$182*'Inputs'!$F$145*('1. Customers'!$C$4/'Inputs'!$F$182)^'Inputs'!$F$181 | E19: Regulatory change + tech transformation; held unallocated like joint costs
B20: TOTAL OPERATING COSTS (unit + HO share + change) | C20: ='4. Running Costs'!$C$10+'4. Running Costs'!$C$17+'4. Running Costs'!$C$19
B21: Operating cost per customer | C21: ='4. Running Costs'!$C$20/'1. Customers'!$C$4
B23: COST ATTRIBUTION MEMO (ABC to the causality limit — see Unit Economics tab)
B24: RM cost (attributed to lending products as acquisition cost) | C24: ='3. HR & Activity'!$H$37
B25: Activity-driven servicing cost (analyst + service payroll) | C25: ='3. HR & Activity'!$H$38+'3. HR & Activity'!$H$39
B26: Supervision & workplace pool (managers, premises, depreciation, other) | C26: ='3. HR & Activity'!$H$40+'4. Running Costs'!$C$4+'4. Running Costs'!$C$5+'4. Running Costs'!$C$6 | E26: Driver: staff time — follows each product's share of servicing + RM cost
B27: Head-office tech attributed to named processes (tab 3 register) | C27: ='3. HR & Activity'!$H$98
B28: Head-office risk attributed to named processes (tab 3 register) | C28: ='3. HR & Activity'!$H$99
B29: Head-office corporate attributed to named processes (tab 3 register) | C29: ='3. HR & Activity'!$H$100
B30: Churn-replacement acquisition marketing attributed by driver (new customers won) | C30: ='4. Running Costs'!$C$16
B31: UNALLOCATED JOINT COSTS (brand, exec, finance, platform build, pool remainders) | C31: ='4. Running Costs'!$C$17-'3. HR & Activity'!$H$97-'4. Running Costs'!$C$30 | E31: Shrinks pound for pound as processes are named on the tab 3 register — costs are carved OUT of the pools, never added on top, so the total never moves. No causal driver exists for what remains; held as a portfolio hurdle, not forced into products.
B33: MEMO — cost base with a named process owner | C33: ='4. Running Costs'!$C$25+'4. Running Costs'!$C$24+'3. HR & Activity'!$H$97+'4. Running Costs'!$C$30 | E33: Activity-driven payroll + RM cost + named head-office processes. Everything else has no process to improve.
B34: …as a share of total operating costs | C34: ='4. Running Costs'!$C$33/'4. Running Costs'!$C$20 | E34: The model's own assessment of its causal completeness. It rises as the head-office register fills.

Sheet 5. Risk & Capital
B1: STEP 3 — INVESTMENT COSTS: EXPECTED LOSSES, CAPITAL & REQUIRED RETURN
B3: EXPECTED CREDIT LOSSES
B4: Lending product | C4: Total balances (£) | D4: Gross PD | E4: Effective PD (after RM stewardship) | F4: LGD | G4: Expected loss (£/yr) | H4: EL per unit (£)
B5: Business overdrafts | C5: ='1. Customers'!$E$15 | D5: ='Inputs'!$F$77 | E5: =D5*(1-'Inputs'!$F$167*'Inputs'!$F$166) | F5: ='Inputs'!$F$78 | G5: =C5*E5*F5 | H5: =G5/'1. Customers'!$C$15
B6: Term loans & comm. mortgages | C6: ='1. Customers'!$E$16 | D6: ='Inputs'!$F$79 | E6: =D6*(1-'Inputs'!$F$167*'Inputs'!$F$166) | F6: ='Inputs'!$F$80 | G6: =C6*E6*F6 | H6: =G6/'1. Customers'!$C$16
B7: Asset finance | C7: ='1. Customers'!$E$17 | D7: ='Inputs'!$F$81 | E7: =D7*(1-'Inputs'!$F$167*'Inputs'!$F$166) | F7: ='Inputs'!$F$82 | G7: =C7*E7*F7 | H7: =G7/'1. Customers'!$C$17
B8: Invoice finance | C8: ='1. Customers'!$E$18 | D8: ='Inputs'!$F$83 | E8: =D8*(1-'Inputs'!$F$167*'Inputs'!$F$166) | F8: ='Inputs'!$F$84 | G8: =C8*E8*F8 | H8: =G8/'1. Customers'!$C$18
B9: Business credit cards | C9: ='1. Customers'!$E$19 | D9: ='Inputs'!$F$85 | E9: =D9 | F9: ='Inputs'!$F$86 | G9: =C9*E9*F9 | H9: =G9/'1. Customers'!$C$19
B10: TOTAL EXPECTED LOSSES | G10: =SUM(G5:G9)
B11: Effective PD = gross PD × (1 − stewardship PD reduction × RM-covered share of balances). Cards are unmanaged, so uncovered.
B13: CAPITAL & REQUIRED RETURN
B14: Credit risk-weighted assets | C14: ='1. Customers'!$E$15*'Inputs'!$F$87+'1. Customers'!$E$16*'Inputs'!$F$88+'1. Customers'!$E$17*'Inputs'!$F$89+'1. Customers'!$E$18*'Inputs'!$F$90+'1. Customers'!$E$19*'Inputs'!$F$91 | I14: Balances × risk weights
B15: Operational risk-weighted assets | C15: ='2. Revenues'!$M$14*'Inputs'!$F$92 | I15: Basic-indicator proxy: gross income × 1.875
B16: TOTAL RWAs | C16: ='5. Risk & Capital'!$C$14+'5. Risk & Capital'!$C$15
B17: Equity allocated to the operating unit | C17: ='5. Risk & Capital'!$C$16*'Inputs'!$F$93 | I17: RWAs × capital ratio
B18: Equity investment benefit (equity earns Bank Rate) | C18: ='5. Risk & Capital'!$C$17*'Inputs'!$F$8 | I18: Added to income in the P&L — equity funds assets so it earns the transfer price
B19: Required return on equity (pre-tax equivalent shown post-tax in P&L) | C19: ='5. Risk & Capital'!$C$17*'Inputs'!$F$94 | I19: Equity × cost of equity — the Simanis 'second-level investment cost'

Sheet 6. Unit Economics
